Workbook
Name k_n: 'Calc'!$B$26
Name k_nh: 'Calc'!$B$27
Name k_ng: 'Calc'!$B$28
Name k_unit: 'Calc'!$B$29
Name k_run: 'Calc'!$B$30
Name k_xd: 'Calc'!$B$31
Name k_gluOn: 'Calc'!$B$32
Name k_gluU: 'Calc'!$B$33
Name k_gd: 'Calc'!$B$34
Name k_dup: 'Calc'!$B$35
Name k_lo: 'Calc'!$B$36
Name k_hi: 'Calc'!$B$37
Name k_rng: 'Calc'!$B$38
Name k_mx: 'Calc'!$B$39
Name k_sx: 'Calc'!$B$40
Name k_rest: 'Calc'!$B$41
Name k_lamin: 'Calc'!$B$42
Name k_base: 'Calc'!$B$43
Name k_lamax: 'Calc'!$B$44
Name k_ymean: 'Calc'!$B$45
Name k_sst: 'Calc'!$B$46
Name k_model: 'Calc'!$B$47
Name k_mexp: 'Calc'!$B$48
Name k_m1: 'Calc'!$B$49
Name k_m2: 'Calc'!$B$50
Name k_roi: 'Calc'!$B$51
Name k_hrdeg: 'Calc'!$B$52
Name k_gfree: 'Calc'!$B$53
Name k_x2nd: 'Calc'!$B$54
Name k_xn1: 'Calc'!$B$55
Name k_yfirst: 'Calc'!$B$56
Name k_ylast: 'Calc'!$B$57
Name k_dur: 'Calc'!$B$58
Name k_p2ok: 'Calc'!$B$61
Name k_p2_0: 'Calc'!$B$62
Name k_p2_1: 'Calc'!$B$63
Name k_p2_2: 'Calc'!$B$64
Name k_p3ok: 'Calc'!$B$65
Name k_p3_0: 'Calc'!$B$66
Name k_p3_1: 'Calc'!$B$67
Name k_p3_2: 'Calc'!$B$68
Name k_p3_3: 'Calc'!$B$69
Name k_p4ok: 'Calc'!$B$70
Name k_p4_0: 'Calc'!$B$71
Name k_p4_1: 'Calc'!$B$72
Name k_p4_2: 'Calc'!$B$73
Name k_p4_3: 'Calc'!$B$74
Name k_p4_4: 'Calc'!$B$75
Name k_eok: 'Calc'!$B$76
Name k_ea: 'Calc'!$B$77
Name k_eb: 'Calc'!$B$78
Name k_ec: 'Calc'!$B$79
Name k_fitok: 'Calc'!$I$82
Name k_s0: 'Calc'!$B$88
Name k_s1: 'Calc'!$B$89
Name k_s2: 'Calc'!$B$90
Name k_s3: 'Calc'!$B$91
Name k_s4: 'Calc'!$B$92
Name k_r2: 'Calc'!$B$93
Name k_rmse: 'Calc'!$B$94

Sheet Anleitung
A1: Laktatdiagnostik – Excel-Version
A2: Nachbau der Webapp „Laktatdiagnostik – Auswertung“ (Stufentest mit LT1/LT2, Modellvergleich, Trainingsbereichen). Alle Ergebnisse sind Formeln ohne Makros.
A4: So wird die Mappe benutzt
A5: 1. Blatt „Eingabe“: Stammdaten, Protokoll und die Messwerte je Stufe (Belastung, Laktat, HF, optional Glukose) in die gelben Felder eintragen.
A6: 2. Rechts im Blatt „Eingabe“ Kurvenmodell, LT1-/LT2-Verfahren und die übrigen Optionen aus den Auswahllisten wählen.
A7: 3. Blatt „Auswertung“: Schwellen, Hinweise, Trainingsbereiche, Laktatstufen-Tabelle sowie Laktat- und HF-Diagramm.
A8: 4. Blatt „Verfahren“: alle 21 Schwellenverfahren und der Modellvergleich (Poly 2/3/4, Exponentiell).
A9: 5. Blatt „Diagramme“: Laktatäquivalent, Log-Log-Darstellung und Glukoseverlauf.
A10: 6. Blatt „Bericht“: druckfertiger A4-Bericht (Datei › Drucken oder Als PDF speichern).
A11: 7. LT1/LT2 manuell verschieben: Wert in Eingabe!I15 bzw. I16 eintragen (leer = Algorithmus). Bereichsgrenzen manuell: Eingabe!I26–I30.
A12: 8. Tests speichern: Datei unter neuem Namen sichern (ersetzt „Test speichern“ und JSON-Export der Webapp). Beispieldaten im Blatt „Beispiele“.
A14: Unterschiede zur Webapp
... A27: Die Schwellen sind modell- und verfahrensabhängige Schätzungen. LT2 ist nicht per Definition MLSS oder Critical Speed/Power. Die Voreinstellungen der Trainingsbereiche sind Konvention.

Sheet Eingabe
A1: Laktatdiagnostik – Eingabe
A2: Gelb hinterlegte Felder mit blauer Schrift sind Eingaben. Alles andere wird berechnet. Dezimalzahlen wie in Excel üblich eingeben (z. B. 10,5). Leere Zeilen werden ignoriert, Stufen nach Belastung sortiert.
A3: Athlet:in und Protokoll | H3: Auswertung
A4: Name | B4: Mayer Elisabeth | D4: Stufendauer [min] | E4: 3 | H4: Kurvenmodell Laktat | I4: Polynom 3. Grades (Standard für Dmax)
A5: Geburtsdatum | B5: 41105 | D5: Stufenhöhe | E5: 1,5 km/h | H5: LT1-Verfahren | I5: LTP1 (Hofmann/Pokan)
A6: Testdatum | B6: 46287 | D6: Probenentnahme | E6: Kapillar Ohrläppchen | H6: LT2-Verfahren | I6: LTP2 (Hofmann/Pokan)
A7: Größe [cm] | B7: 155.1 | D7: Matrix | E7: Vollblut | H7: LTP1-Suchbereich bis [% vmax] | I7: 70
A8: Masse [kg] | B8: 40.4 | D8: Analysator | H8: Baseline für Δ-Verfahren | I8: niedrigster Stufenwert
A9: Ergometer | B9: Laufband (km/h) | D9: Ruhelaktat [mmol/L] | E9: 1.6 | H9: Modell Herzfrequenz | I9: Polynom 2. Grades
A10: Testleitung | B10: Ernst Johannes, BSc | D10: ="Ruheglukose ["&k_gluU&"]" | E10: 81 | H10: Hilfsgeraden-Konstruktion | I10: korrigiert: nie unterhalb der Laktatkurve
A11: Bemerkung | H11: Glukose je Stufe erfassen | I11: Nein
A12: Institution / Labor | H12: Glukose-Einheit | I12: mg/dL
A13: Adresse und Kontakt
H14: Schwellen manuell setzen (leer = Algorithmus)
A15: Messwerte je Stufe | H15: ="LT1 manuell ["&k_unit&"]"
A16: Stufe | B16: Zeit [mm:ss] | C16: ="Belastung ["&k_unit&"]" | D16: Laktat [mmol/L] | E16: HF [1/min] | F16: ="Glukose ["&k_gluU&"]" | H16: ="LT2 manuell ["&k_unit&"]"
A17: 1 | B17: 03:00 | C17: 6 | D17: 2.2 | E17: 145
A18: 2 | B18: 06:00 | C18: 7.5 | D18: 2.3 | E18: 167 | H18: Regeln für Trainingsbereiche
A19: 3 | B19: 09:00 | C19: 9 | D19: 2.7 | E19: 184 | H19: A1 ab [% LT1] | I19: 81
A20: 4 | B20: 12:00 | C20: 10.5 | D20: 3.5 | E20: 193 | H20: A2 bis [% der Strecke LT1→LT2] | I20: 52
A21: 5 | B21: 15:00 | C21: 12 | D21: 5.1 | E21: 200 | H21: A3 bis [% LT2] | I21: 104.5
A22: 6 | B22: 18:00 | C22: 13.5 | D22: 8.2 | E22: 207 | H22: A4 bis [% vmax] | I22: 98
A23: 7 | B23: 19:30 | C23: 14.25 | D23: 9.3 | E23: 208 | H23: Voreinstellung (LSA-Beispielauswertung): 81 / 52 / 104,5 / 98. Konvention, keine physiologische Größe.
A24: 8
A25: 9 | H25: Bereichsgrenzen manuell (leer = Regel)
A26: 10 | H26: ="A0|A1 ["&k_unit&"]"
A27: 11 | H27: ="A1|A2 (sonst = LT1) ["&k_unit&"]"
A28: 12 | H28: ="A2|A3 ["&k_unit&"]"
A29: 13 | H29: ="A3|A4 ["&k_unit&"]"
A30: 14 | H30: ="A4 Ende ["&k_unit&"]"
A31: 15
A32: 16 | H32: Beispieldaten: Blatt „Beispiele“. Zum Speichern eines Tests die Datei unter neuem Namen sichern.
A33: 17
A34: 18
A35: 19
A36: 20
A38: Zeit als Text eingeben (z. B. 03:00). Glukose wird nur ausgewertet, wenn rechts „Glukose je Stufe erfassen = Ja“.

Sheet Auswertung
A1: =IF(Eingabe!$B$4<>"",Eingabe!$B$4&IF(ISNUMBER(Eingabe!$B$6)," · Test vom "&TEXT(Eingabe!$B$6,"DD.MM.YYYY"),""),"Laktatdiagnostik – Auswertung")
A2: Stufentest-Auswertung mit LT1/LT2, Modellvergleich und Trainingsbereichen. Alle Werte berechnen sich aus dem Blatt „Eingabe“.
A3: =IF(k_ok,"",k_err)
A5: Schwellen
B6: LT1 | C6: LT2 | D6: Maximum
A7: Verfahren | B7: =IF(k_ok,Eingabe!$I$5&IF(k_man1," (manuell)",""),"–") | C7: =IF(k_ok,Eingabe!$I$6&IF(k_man2," (manuell)",""),"–") | D7: ="letzte Stufe"
A8: ="Belastung ["&k_unit&"]" | B8: =IF(ISNUMBER(k_x1),ROUND(k_x1,k_xd),"–") | C8: =IF(ISNUMBER(k_x2),ROUND(k_x2,k_xd),"–") | D8: =IF(k_ok,ROUND(k_hi,k_xd),"–")
A9: Pace [min/km] | B9: =IF(k_run,IF(N(k_x1)>0,INT(ROUND(3600/(k_x1),0)/60)&":"&TEXT(MOD(ROUND(3600/(k_x1),0),60),"00"),"–"),"–") | C9: =IF(k_run,IF(N(k_x2)>0,INT(ROUND(3600/(k_x2),0)/60)&":"&TEXT(MOD(ROUND(3600/(k_x2),0),60),"00"),"–"),"–") | D9: =IF(AND(k_ok,k_run),IF(N(k_hi)>0,INT(ROUND(3600/(k_hi),0)/60)&":"&TEXT(MOD(ROUND(3600/(k_hi),0),60),"00"),"–"),"–")
A10: Geschwindigkeit [m/s] | B10: =IF(AND(k_run,ISNUMBER(k_x1)),ROUND(k_x1/3.6,2),"–") | C10: =IF(AND(k_run,ISNUMBER(k_x2)),ROUND(k_x2/3.6,2),"–") | D10: =IF(AND(k_ok,k_run),ROUND(k_hi/3.6,2),"–")
A11: Laktat [mmol/L] | B11: =IF(ISNUMBER(k_la1),ROUND(k_la1,2),"–") | C11: =IF(ISNUMBER(k_la2),ROUND(k_la2,2),"–") | D11: =IF(k_ok,k_lamax,"–")
A12: Herzfrequenz [1/min] | B12: =IF(ISNUMBER(k_hr1),ROUND(k_hr1,0),"–") | C12: =IF(ISNUMBER(k_hr2),ROUND(k_hr2,0),"–") | D12: =IF(ISNUMBER(k_hrmax),k_hrmax,"–")
A13: % HFmax | B13: =IF(AND(ISNUMBER(k_hr1),ISNUMBER(k_hrmax)),ROUND(k_hr1/k_hrmax*100,1),"–") | C13: =IF(AND(ISNUMBER(k_hr2),ISNUMBER(k_hrmax)),ROUND(k_hr2/k_hrmax*100,1),"–") | D13: =IF(ISNUMBER(k_hrmax),100,"–")
A14: Anteil vmax [%] | B14: =IF(ISNUMBER(k_x1),ROUND(k_x1/k_hi*100,1),"–") | C14: =IF(ISNUMBER(k_x2),ROUND(k_x2/k_hi*100,1),"–") | D14: =IF(k_ok,100,"–")
A15: Ruhelaktat [mmol/L] | B15: ="–" | C15: ="–" | D15: =IF(ISNUMBER(k_rest),k_rest,"–")
A16: ="LT2 − LT1 ["&k_unit&"]" | B16: ="–" | C16: ="–" | D16: =IF(AND(ISNUMBER(k_x1),ISNUMBER(k_x2)),ROUND(k_x2-k_x1,k_xd),"–")
A17: Algorithmus (vor manueller Korrektur) | B17: =IF(ISNUMBER(k_a1x),ROUND(k_a1x,k_xd),"–") | C17: =IF(ISNUMBER(k_a2x),ROUND(k_a2x,k_xd),"–") | D17: =""
A18: Manuelle Korrektur von LT1/LT2 und Bereichsgrenzen im Blatt „Eingabe“ (Spalte I).
A20: Hinweise zur Auswertung
A21: =IFERROR(INDEX(Calc!$B$190:$B$204,MATCH(1,Calc!$C$190:$C$204,0)),"")
A22: =IFERROR(INDEX(Calc!$B$190:$B$204,MATCH(2,Calc!$C$190:$C$204,0)),"")
A23: =IFERROR(INDEX(Calc!$B$190:$B$204,MATCH(3,Calc!$C$190:$C$204,0)),"")
A24: =IFERROR(INDEX(Calc!$B$190:$B$204,MATCH(4,Calc!$C$190:$C$204,0)),"")
A25: =IFERROR(INDEX(Calc!$B$190:$B$204,MATCH(5,Calc!$C$190:$C$204,0)),"")
A26: =IFERROR(INDEX(Calc!$B$190:$B$204,MATCH(6,Calc!$C$190:$C$204,0)),"")
A27: =IFERROR(INDEX(Calc!$B$190:$B$204,MATCH(7,Calc!$C$190:$C$204,0)),"")
A28: =IFERROR(INDEX(Calc!$B$190:$B$204,MATCH(8,Calc!$C$190:$C$204,0)),"")
A29: =IFERROR(INDEX(Calc!$B$190:$B$204,MATCH(9,Calc!$C$190:$C$204,0)),"")
A30: =IFERROR(INDEX(Calc!$B$190:$B$204,MATCH(10,Calc!$C$190:$C$204,0)),"")
A31: =IFERROR(INDEX(Calc!$B$190:$B$204,MATCH(11,Calc!$C$190:$C$204,0)),"")
A32: =IFERROR(INDEX(Calc!$B$190:$B$204,MATCH(12,Calc!$C$190:$C$204,0)),"")
A33: =IFERROR(INDEX(Calc!$B$190:$B$204,MATCH(13,Calc!$C$190:$C$204,0)),"")
A34: =IFERROR(INDEX(Calc!$B$190:$B$204,MATCH(14,Calc!$C$190:$C$204,0)),"")
A35: =IFERROR(INDEX(Calc!$B$190:$B$204,MATCH(15,Calc!$C$190:$C$204,0)),"")
A37: Trainingsbereiche
A38: Trainingsbereich | B38: HF von | C38: HF bis | D38: ="Belastung von ["&k_unit&"]" | E38: ="Belastung bis ["&k_unit&"]" | F38: Pace von | G38: Pace bis | H38: Laktat bis | I38: manuell
A39: A0 · Regeneration/Kompensation | B39: ="" | C39: =IF(k_zok,IFERROR(ROUND(IF(k_hrok,k_h0+k_h1*(k_z0)+k_h2*(k_z0)^2,""),0),"–"),"–") | D39: ="" | E39: =IF(k_zok,ROUND(k_z0,k_xd),"–") | F39: ="" | G39: =IF(AND(k_zok,k_run),IF(N(k_z0)>0,INT(ROUND(3600/(k_z0),0)/60)&":"&TEXT(MOD(ROUND(3600/(k_z0),0),60),"00"),"–"),"") | H39: =IF(k_zok,ROUND(IF(k_mexp,k_ea+k_eb*EXP(k_ec*((MIN(k_z0,k_hi))-k_mx)/k_sx),k_s0+((MIN(k_z0,k_hi))-k_mx)/k_sx*(k_s1+((MIN(k_z0,k_hi))-k_mx)/k_sx*(k_s2+((MIN(k_z0,k_hi))-k_mx)/k_sx*(k_s3+((MIN(k_z0,k_hi))-k_mx)/k_sx*k_s4)))),2),"–") | I39: =IF(k_zm0,"• manuell",IF(0=1,"folgt LT1",""))
A40: A1 · Extensives Ausdauertraining 1 | B40: =IF(AND(k_zok,1>0),IFERROR(ROUND(IF(k_hrok,k_h0+k_h1*(k_z0)+k_h2*(k_z0)^2,""),0),"–"),"") | C40: =IF(k_zok,IFERROR(ROUND(IF(k_hrok,k_h0+k_h1*(k_z1)+k_h2*(k_z1)^2,""),0),"–"),"–") | D40: =IF(AND(k_zok,1>0),ROUND(k_z0,k_xd),"") | E40: =IF(k_zok,ROUND(k_z1,k_xd),"–") | F40: =IF(AND(k_zok,k_run),IF(N(k_z0)>0,INT(ROUND(3600/(k_z0),0)/60)&":"&TEXT(MOD(ROUND(3600/(k_z0),0),60),"00"),"–"),"") | G40: =IF(AND(k_zok,k_run),IF(N(k_z1)>0,INT(ROUND(3600/(k_z1),0)/60)&":"&TEXT(MOD(ROUND(3600/(k_z1),0),60),"00"),"–"),"") | H40: =IF(k_zok,ROUND(IF(k_mexp,k_ea+k_eb*EXP(k_ec*((MIN(k_z1,k_hi))-k_mx)/k_sx),k_s0+((MIN(k_z1,k_hi))-k_mx)/k_sx*(k_s1+((MIN(k_z1,k_hi))-k_mx)/k_sx*(k_s2+((MIN(k_z1,k_hi))-k_mx)/k_sx*(k_s3+((MIN(k_z1,k_hi))-k_mx)/k_sx*k_s4)))),2),"–") | I40: =IF(k_zm1,"• manuell",IF(1=1,"folgt LT1",""))
A41: A2 · Extensives Ausdauertraining 2 | B41: =IF(AND(k_zok,2>0),IFERROR(ROUND(IF(k_hrok,k_h0+k_h1*(k_z1)+k_h2*(k_z1)^2,""),0),"–"),"") | C41: =IF(k_zok,IFERROR(ROUND(IF(k_hrok,k_h0+k_h1*(k_z2)+k_h2*(k_z2)^2,""),0),"–"),"–") | D41: =IF(AND(k_zok,2>0),ROUND(k_z1,k_xd),"") | E41: =IF(k_zok,ROUND(k_z2,k_xd),"–") | F41: =IF(AND(k_zok,k_run),IF(N(k_z1)>0,INT(ROUND(3600/(k_z1),0)/60)&":"&TEXT(MOD(ROUND(3600/(k_z1),0),60),"00"),"–"),"") | G41: =IF(AND(k_zok,k_run),IF(N(k_z2)>0,INT(ROUND(3600/(k_z2),0)/60)&":"&TEXT(MOD(ROUND(3600/(k_z2),0),60),"00"),"–"),"") | H41: =IF(k_zok,ROUND(IF(k_mexp,k_ea+k_eb*EXP(k_ec*((MIN(k_z2,k_hi))-k_mx)/k_sx),k_s0+((MIN(k_z2,k_hi))-k_mx)/k_sx*(k_s1+((MIN(k_z2,k_hi))-k_mx)/k_sx*(k_s2+((MIN(k_z2,k_hi))-k_mx)/k_sx*(k_s3+((MIN(k_z2,k_hi))-k_mx)/k_sx*k_s4)))),2),"–") | I41: =IF(k_zm2,"• manuell",IF(2=1,"folgt LT1",""))
A42: A3 · Intensives Ausdauertraining | B42: =IF(AND(k_zok,3>0),IFERROR(ROUND(IF(k_hrok,k_h0+k_h1*(k_z2)+k_h2*(k_z2)^2,""),0),"–"),"") | C42: =IF(k_zok,IFERROR(ROUND(IF(k_hrok,k_h0+k_h1*(k_z3)+k_h2*(k_z3)^2,""),0),"–"),"–") | D42: =IF(AND(k_zok,3>0),ROUND(k_z2,k_xd),"") | E42: =IF(k_zok,ROUND(k_z3,k_xd),"–") | F42: =IF(AND(k_zok,k_run),IF(N(k_z2)>0,INT(ROUND(3600/(k_z2),0)/60)&":"&TEXT(MOD(ROUND(3600/(k_z2),0),60),"00"),"–"),"") | G42: =IF(AND(k_zok,k_run),IF(N(k_z3)>0,INT(ROUND(3600/(k_z3),0)/60)&":"&TEXT(MOD(ROUND(3600/(k_z3),0),60),"00"),"–"),"") | H42: =IF(k_zok,ROUND(IF(k_mexp,k_ea+k_eb*EXP(k_ec*((MIN(k_z3,k_hi))-k_mx)/k_sx),k_s0+((MIN(k_z3,k_hi))-k_mx)/k_sx*(k_s1+((MIN(k_z3,k_hi))-k_mx)/k_sx*(k_s2+((MIN(k_z3,k_hi))-k_mx)/k_sx*(k_s3+((MIN(k_z3,k_hi))-k_mx)/k_sx*k_s4)))),2),"–") | I42: =IF(k_zm3,"• manuell",IF(3=1,"folgt LT1",""))
A43: A4 · Entwicklungsbereich | B43: =IF(AND(k_zok,4>0),IFERROR(ROUND(IF(k_hrok,k_h0+k_h1*(k_z3)+k_h2*(k_z3)^2,""),0),"–"),"") | C43: =IF(k_zok,IFERROR(ROUND(IF(k_hrok,k_h0+k_h1*(k_z4)+k_h2*(k_z4)^2,""),0),"–"),"–") | D43: =IF(AND(k_zok,4>0),ROUND(k_z3,k_xd),"") | E43: =IF(k_zok,ROUND(k_z4,k_xd),"–") | F43: =IF(AND(k_zok,k_run),IF(N(k_z3)>0,INT(ROUND(3600/(k_z3),0)/60)&":"&TEXT(MOD(ROUND(3600/(k_z3),0),60),"00"),"–"),"") | G43: =IF(AND(k_zok,k_run),IF(N(k_z4)>0,INT(ROUND(3600/(k_z4),0)/60)&":"&TEXT(MOD(ROUND(3600/(k_z4),0),60),"00"),"–"),"") | H43: =IF(k_zok,ROUND(IF(k_mexp,k_ea+k_eb*EXP(k_ec*((MIN(k_z4,k_hi))-k_mx)/k_sx),k_s0+((MIN(k_z4,k_hi))-k_mx)/k_sx*(k_s1+((MIN(k_z4,k_hi))-k_mx)/k_sx*(k_s2+((MIN(k_z4,k_hi))-k_mx)/k_sx*(k_s3+((MIN(k_z4,k_hi))-k_mx)/k_sx*k_s4)))),2),"–") | I43: =IF(k_zm4,"• manuell",IF(4=1,"folgt LT1",""))
...

Sheet Verfahren
A1: Alle Schwellenverfahren
A2: Berechnet mit dem gewählten Kurvenmodell. Keine Extrapolation über den Messbereich hinaus. LT1/LT2-Auswahl im Blatt „Eingabe“.
A4: Verfahren | B4: Zielkonstrukt | C4: ="Belastung ["&k_unit&"]" | D4: Laktat | E4: HF | F4: Hinweis | G4: als LT1 | H4: als LT2
A5: Erster Laktatanstieg (LT1)
A6: LTP1 (Hofmann/Pokan) | B6: erster Laktatumstellpunkt | C6: =IF(AND(k_ok,ISNUMBER(INDEX(VCalc!$C$5:$W$25,1,1+5*(k_model-1)+0))),ROUND(INDEX(VCalc!$C$5:$W$25,1,1+5*(k_model-1)+0),k_xd),"–") | D6: =IF(AND(k_ok,ISNUMBER(INDEX(VCalc!$C$5:$W$25,1,1+5*(k_model-1)+0))),ROUND(INDEX(VCalc!$C$5:$W$25,1,1+5*(k_model-1)+1),2),"–") | E6: =IF(AND(k_ok,ISNUMBER(INDEX(VCalc!$C$5:$W$25,1,1+5*(k_model-1)+0))),IFERROR(ROUND(IF(k_hrok,k_h0+k_h1*(INDEX(VCalc!$C$5:$W$25,1,1+5*(k_model-1)+0))+k_h2*(INDEX(VCalc!$C$5:$W$25,1,1+5*(k_model-1)+0))^2,""),0),"–"),"–") | F6: =IF(k_ok,MID(IF(INDEX(VCalc!$C$5:$W$25,1,1+5*(k_model-1)+2)<>""," · "&INDEX(VCalc!$C$5:$W$25,1,1+5*(k_model-1)+2),"")&IF(INDEX(VCalc!$C$5:$W$25,1,1+5*(k_model-1)+3)<>""," · "&INDEX(VCalc!$C$5:$W$25,1,1+5*(k_model-1)+3),"")&IF(INDEX(VCalc!$C$5:$W$25,1,1+5*(k_model-1)+4)<>""," · "&INDEX(VCalc!$C$5:$W$25,1,1+5*(k_model-1)+4),""),4,500),"") | G6: =IF(k_m1=1,"● LT1","") | H6: =IF(k_m2=1,"● LT2","")
A7: LTP1 (3-Phasen global) | B7: erster Laktatumstellpunkt | C7: =IF(AND(k_ok,ISNUMBER(INDEX(VCalc!$C$5:$W$25,2,1+5*(k_model-1)+0))),ROUND(INDEX(VCalc!$C$5:$W$25,2,1+5*(k_model-1)+0),k_xd),"–") | D7: =IF(AND(k_ok,ISNUMBER(INDEX(VCalc!$C$5:$W$25,2,1+5*(k_model-1)+0))),ROUND(INDEX(VCalc!$C$5:$W$25,2,1+5*(k_model-1)+1),2),"–") | E7: =IF(AND(k_ok,ISNUMBER(INDEX(VCalc!$C$5:$W$25,2,1+5*(k_model-1)+0))),IFERROR(ROUND(IF(k_hrok,k_h0+k_h1*(INDEX(VCalc!$C$5:$W$25,2,1+5*(k_model-1)+0))+k_h2*(INDEX(VCalc!$C$5:$W$25,2,1+5*(k_model-1)+0))^2,""),0),"–"),"–") | F7: =IF(k_ok,MID(IF(INDEX(VCalc!$C$5:$W$25,2,1+5*(k_model-1)+2)<>""," · "&INDEX(VCalc!$C$5:$W$25,2,1+5*(k_model-1)+2),"")&IF(INDEX(VCalc!$C$5:$W$25,2,1+5*(k_model-1)+3)<>""," · "&INDEX(VCalc!$C$5:$W$25,2,1+5*(k_model-1)+3),"")&IF(INDEX(VCalc!$C$5:$W$25,2,1+5*(k_model-1)+4)<>""," · "&INDEX(VCalc!$C$5:$W$25,2,1+5*(k_model-1)+4),""),4,500),"") | G7: =IF(k_m1=2,"● LT1","") | H7: =IF(k_m2=2,"● LT2","")
A8: Log-Log (Beaver) | B8: erster Laktatanstieg | C8: =IF(AND(k_ok,ISNUMBER(INDEX(VCalc!$C$5:$W$25,3,1+5*(k_model-1)+0))),ROUND(INDEX(VCalc!$C$5:$W$25,3,1+5*(k_model-1)+0),k_xd),"–") | D8: =IF(AND(k_ok,ISNUMBER(INDEX(VCalc!$C$5:$W$25,3,1+5*(k_model-1)+0))),ROUND(INDEX(VCalc!$C$5:$W$25,3,1+5*(k_model-1)+1),2),"–") | E8: =IF(AND(k_ok,ISNUMBER(INDEX(VCalc!$C$5:$W$25,3,1+5*(k_model-1)+0))),IFERROR(ROUND(IF(k_hrok,k_h0+k_h1*(INDEX(VCalc!$C$5:$W$25,3,1+5*(k_model-1)+0))+k_h2*(INDEX(VCalc!$C$5:$W$25,3,1+5*(k_model-1)+0))^2,""),0),"–"),"–") | F8: =IF(k_ok,MID(IF(INDEX(VCalc!$C$5:$W$25,3,1+5*(k_model-1)+2)<>""," · "&INDEX(VCalc!$C$5:$W$25,3,1+5*(k_model-1)+2),"")&IF(INDEX(VCalc!$C$5:$W$25,3,1+5*(k_model-1)+3)<>""," · "&INDEX(VCalc!$C$5:$W$25,3,1+5*(k_model-1)+3),"")&IF(INDEX(VCalc!$C$5:$W$25,3,1+5*(k_model-1)+4)<>""," · "&INDEX(VCalc!$C$5:$W$25,3,1+5*(k_model-1)+4),""),4,500),"") | G8: =IF(k_m1=3,"● LT1","") | H8: =IF(k_m2=3,"● LT2","")
A9: Baseline + 0,5 mmol/L | B9: erster Laktatanstieg | C9: =IF(AND(k_ok,ISNUMBER(INDEX(VCalc!$C$5:$W$25,4,1+5*(k_model-1)+0))),ROUND(INDEX(VCalc!$C$5:$W$25,4,1+5*(k_model-1)+0),k_xd),"–") | D9: =IF(AND(k_ok,ISNUMBER(INDEX(VCalc!$C$5:$W$25,4,1+5*(k_model-1)+0))),ROUND(INDEX(VCalc!$C$5:$W$25,4,1+5*(k_model-1)+1),2),"–") | E9: =IF(AND(k_ok,ISNUMBER(INDEX(VCalc!$C$5:$W$25,4,1+5*(k_model-1)+0))),IFERROR(ROUND(IF(k_hrok,k_h0+k_h1*(INDEX(VCalc!$C$5:$W$25,4,1+5*(k_model-1)+0))+k_h2*(INDEX(VCalc!$C$5:$W$25,4,1+5*(k_model-1)+0))^2,""),0),"–"),"–") | F9: =IF(k_ok,MID(IF(INDEX(VCalc!$C$5:$W$25,4,1+5*(k_model-1)+2)<>""," · "&INDEX(VCalc!$C$5:$W$25,4,1+5*(k_model-1)+2),"")&IF(INDEX(VCalc!$C$5:$W$25,4,1+5*(k_model-1)+3)<>""," · "&INDEX(VCalc!$C$5:$W$25,4,1+5*(k_model-1)+3),"")&IF(INDEX(VCalc!$C$5:$W$25,4,1+5*(k_model-1)+4)<>""," · "&INDEX(VCalc!$C$5:$W$25,4,1+5*(k_model-1)+4),""),4,500),"") | G9: =IF(k_m1=4,"● LT1","") | H9: =IF(k_m2=4,"● LT2","")
A10: Minimales Laktatäquivalent | B10: erster Laktatanstieg | C10: =IF(AND(k_ok,ISNUMBER(INDEX(VCalc!$C$5:$W$25,5,1+5*(k_model-1)+0))),ROUND(INDEX(VCalc!$C$5:$W$25,5,1+5*(k_model-1)+0),k_xd),"–") | D10: =IF(AND(k_ok,ISNUMBER(INDEX(VCalc!$C$5:$W$25,5,1+5*(k_model-1)+0))),ROUND(INDEX(VCalc!$C$5:$W$25,5,1+5*(k_model-1)+1),2),"–") | E10: =IF(AND(k_ok,ISNUMBER(INDEX(VCalc!$C$5:$W$25,5,1+5*(k_model-1)+0))),IFERROR(ROUND(IF(k_hrok,k_h0+k_h1*(INDEX(VCalc!$C$5:$W$25,5,1+5*(k_model-1)+0))+k_h2*(INDEX(VCalc!$C$5:$W$25,5,1+5*(k_model-1)+0))^2,""),0),"–"),"–") | F10: =IF(k_ok,MID(IF(INDEX(VCalc!$C$5:$W$25,5,1+5*(k_model-1)+2)<>""," · "&INDEX(VCalc!$C$5:$W$25,5,1+5*(k_model-1)+2),"")&IF(INDEX(VCalc!$C$5:$W$25,5,1+5*(k_model-1)+3)<>""," · "&INDEX(VCalc!$C$5:$W$25,5,1+5*(k_model-1)+3),"")&IF(INDEX(VCalc!$C$5:$W$25,5,1+5*(k_model-1)+4)<>""," · "&INDEX(VCalc!$C$5:$W$25,5,1+5*(k_model-1)+4),""),4,500),"") | G10: =IF(k_m1=5,"● LT1","") | H10: =IF(k_m2=5,"● LT2","")
A11: fix 2,0 mmol/L | B11: niedriger fixer Anker | C11: =IF(AND(k_ok,ISNUMBER(INDEX(VCalc!$C$5:$W$25,6,1+5*(k_model-1)+0))),ROUND(INDEX(VCalc!$C$5:$W$25,6,1+5*(k_model-1)+0),k_xd),"–") | D11: =IF(AND(k_ok,ISNUMBER(INDEX(VCalc!$C$5:$W$25,6,1+5*(k_model-1)+0))),ROUND(INDEX(VCalc!$C$5:$W$25,6,1+5*(k_model-1)+1),2),"–") | E11: =IF(AND(k_ok,ISNUMBER(INDEX(VCalc!$C$5:$W$25,6,1+5*(k_model-1)+0))),IFERROR(ROUND(IF(k_hrok,k_h0+k_h1*(INDEX(VCalc!$C$5:$W$25,6,1+5*(k_model-1)+0))+k_h2*(INDEX(VCalc!$C$5:$W$25,6,1+5*(k_model-1)+0))^2,""),0),"–"),"–") | F11: =IF(k_ok,MID(IF(INDEX(VCalc!$C$5:$W$25,6,1+5*(k_model-1)+2)<>""," · "&INDEX(VCalc!$C$5:$W$25,6,1+5*(k_model-1)+2),"")&IF(INDEX(VCalc!$C$5:$W$25,6,1+5*(k_model-1)+3)<>""," · "&INDEX(VCalc!$C$5:$W$25,6,1+5*(k_model-1)+3),"")&IF(INDEX(VCalc!$C$5:$W$25,6,1+5*(k_model-1)+4)<>""," · "&INDEX(VCalc!$C$5:$W$25,6,1+5*(k_model-1)+4),""),4,500),"") | G11: =IF(k_m1=6,"● LT1","") | H11: =IF(k_m2=6,"● LT2","")
A12: Oberer Übergangsbereich (LT2)
A13: LTP2 (Hofmann/Pokan) | B13: zweiter Laktatumstellpunkt | C13: =IF(AND(k_ok,ISNUMBER(INDEX(VCalc!$C$5:$W$25,7,1+5*(k_model-1)+0))),ROUND(INDEX(VCalc!$C$5:$W$25,7,1+5*(k_model-1)+0),k_xd),"–") | D13: =IF(AND(k_ok,ISNUMBER(INDEX(VCalc!$C$5:$W$25,7,1+5*(k_model-1)+0))),ROUND(INDEX(VCalc!$C$5:$W$25,7,1+5*(k_model-1)+1),2),"–") | E13: =IF(AND(k_ok,ISNUMBER(INDEX(VCalc!$C$5:$W$25,7,1+5*(k_model-1)+0))),IFERROR(ROUND(IF(k_hrok,k_h0+k_h1*(INDEX(VCalc!$C$5:$W$25,7,1+5*(k_model-1)+0))+k_h2*(INDEX(VCalc!$C$5:$W$25,7,1+5*(k_model-1)+0))^2,""),0),"–"),"–") | F13: =IF(k_ok,MID(IF(INDEX(VCalc!$C$5:$W$25,7,1+5*(k_model-1)+2)<>""," · "&INDEX(VCalc!$C$5:$W$25,7,1+5*(k_model-1)+2),"")&IF(INDEX(VCalc!$C$5:$W$25,7,1+5*(k_model-1)+3)<>""," · "&INDEX(VCalc!$C$5:$W$25,7,1+5*(k_model-1)+3),"")&IF(INDEX(VCalc!$C$5:$W$25,7,1+5*(k_model-1)+4)<>""," · "&INDEX(VCalc!$C$5:$W$25,7,1+5*(k_model-1)+4),""),4,500),"") | G13: =IF(k_m1=7,"● LT1","") | H13: =IF(k_m2=7,"● LT2","")
A14: LTP2 (3-Phasen global) | B14: zweiter Laktatumstellpunkt | C14: =IF(AND(k_ok,ISNUMBER(INDEX(VCalc!$C$5:$W$25,8,1+5*(k_model-1)+0))),ROUND(INDEX(VCalc!$C$5:$W$25,8,1+5*(k_model-1)+0),k_xd),"–") | D14: =IF(AND(k_ok,ISNUMBER(INDEX(VCalc!$C$5:$W$25,8,1+5*(k_model-1)+0))),ROUND(INDEX(VCalc!$C$5:$W$25,8,1+5*(k_model-1)+1),2),"–") | E14: =IF(AND(k_ok,ISNUMBER(INDEX(VCalc!$C$5:$W$25,8,1+5*(k_model-1)+0))),IFERROR(ROUND(IF(k_hrok,k_h0+k_h1*(INDEX(VCalc!$C$5:$W$25,8,1+5*(k_model-1)+0))+k_h2*(INDEX(VCalc!$C$5:$W$25,8,1+5*(k_model-1)+0))^2,""),0),"–"),"–") | F14: =IF(k_ok,MID(IF(INDEX(VCalc!$C$5:$W$25,8,1+5*(k_model-1)+2)<>""," · "&INDEX(VCalc!$C$5:$W$25,8,1+5*(k_model-1)+2),"")&IF(INDEX(VCalc!$C$5:$W$25,8,1+5*(k_model-1)+3)<>""," · "&INDEX(VCalc!$C$5:$W$25,8,1+5*(k_model-1)+3),"")&IF(INDEX(VCalc!$C$5:$W$25,8,1+5*(k_model-1)+4)<>""," · "&INDEX(VCalc!$C$5:$W$25,8,1+5*(k_model-1)+4),""),4,500),"") | G14: =IF(k_m1=8,"● LT1","") | H14: =IF(k_m2=8,"● LT2","")
A15: Dmax (Cheng) | B15: LT2 | C15: =IF(AND(k_ok,ISNUMBER(INDEX(VCalc!$C$5:$W$25,9,1+5*(k_model-1)+0))),ROUND(INDEX(VCalc!$C$5:$W$25,9,1+5*(k_model-1)+0),k_xd),"–") | D15: =IF(AND(k_ok,ISNUMBER(INDEX(VCalc!$C$5:$W$25,9,1+5*(k_model-1)+0))),ROUND(INDEX(VCalc!$C$5:$W$25,9,1+5*(k_model-1)+1),2),"–") | E15: =IF(AND(k_ok,ISNUMBER(INDEX(VCalc!$C$5:$W$25,9,1+5*(k_model-1)+0))),IFERROR(ROUND(IF(k_hrok,k_h0+k_h1*(INDEX(VCalc!$C$5:$W$25,9,1+5*(k_model-1)+0))+k_h2*(INDEX(VCalc!$C$5:$W$25,9,1+5*(k_model-1)+0))^2,""),0),"–"),"–") | F15: =IF(k_ok,MID(IF(INDEX(VCalc!$C$5:$W$25,9,1+5*(k_model-1)+2)<>""," · "&INDEX(VCalc!$C$5:$W$25,9,1+5*(k_model-1)+2),"")&IF(INDEX(VCalc!$C$5:$W$25,9,1+5*(k_model-1)+3)<>""," · "&INDEX(VCalc!$C$5:$W$25,9,1+5*(k_model-1)+3),"")&IF(INDEX(VCalc!$C$5:$W$25,9,1+5*(k_model-1)+4)<>""," · "&INDEX(VCalc!$C$5:$W$25,9,1+5*(k_model-1)+4),""),4,500),"") | G15: =IF(k_m1=9,"● LT1","") | H15: =IF(k_m2=9,"● LT2","")
A16: Modified Dmax (Bishop) | B16: LT2 | C16: =IF(AND(k_ok,ISNUMBER(INDEX(VCalc!$C$5:$W$25,10,1+5*(k_model-1)+0))),ROUND(INDEX(VCalc!$C$5:$W$25,10,1+5*(k_model-1)+0),k_xd),"–") | D16: =IF(AND(k_ok,ISNUMBER(INDEX(VCalc!$C$5:$W$25,10,1+5*(k_model-1)+0))),ROUND(INDEX(VCalc!$C$5:$W$25,10,1+5*(k_model-1)+1),2),"–") | E16: =IF(AND(k_ok,ISNUMBER(INDEX(VCalc!$C$5:$W$25,10,1+5*(k_model-1)+0))),IFERROR(ROUND(IF(k_hrok,k_h0+k_h1*(INDEX(VCalc!$C$5:$W$25,10,1+5*(k_model-1)+0))+k_h2*(INDEX(VCalc!$C$5:$W$25,10,1+5*(k_model-1)+0))^2,""),0),"–"),"–") | F16: =IF(k_ok,MID(IF(INDEX(VCalc!$C$5:$W$25,10,1+5*(k_model-1)+2)<>""," · "&INDEX(VCalc!$C$5:$W$25,10,1+5*(k_model-1)+2),"")&IF(INDEX(VCalc!$C$5:$W$25,10,1+5*(k_model-1)+3)<>""," · "&INDEX(VCalc!$C$5:$W$25,10,1+5*(k_model-1)+3),"")&IF(INDEX(VCalc!$C$5:$W$25,10,1+5*(k_model-1)+4)<>""," · "&INDEX(VCalc!$C$5:$W$25,10,1+5*(k_model-1)+4),""),4,500),"") | G16: =IF(k_m1=10,"● LT1","") | H16: =IF(k_m2=10,"● LT2","")
A17: Log-Poly-ModDmax | B17: LT2 / MLSS-Schätzer | C17: =IF(AND(k_ok,ISNUMBER(INDEX(VCalc!$C$5:$W$25,11,1+5*(k_model-1)+0))),ROUND(INDEX(VCalc!$C$5:$W$25,11,1+5*(k_model-1)+0),k_xd),"–") | D17: =IF(AND(k_ok,ISNUMBER(INDEX(VCalc!$C$5:$W$25,11,1+5*(k_model-1)+0))),ROUND(INDEX(VCalc!$C$5:$W$25,11,1+5*(k_model-1)+1),2),"–") | E17: =IF(AND(k_ok,ISNUMBER(INDEX(VCalc!$C$5:$W$25,11,1+5*(k_model-1)+0))),IFERROR(ROUND(IF(k_hrok,k_h0+k_h1*(INDEX(VCalc!$C$5:$W$25,11,1+5*(k_model-1)+0))+k_h2*(INDEX(VCalc!$C$5:$W$25,11,1+5*(k_model-1)+0))^2,""),0),"–"),"–") | F17: =IF(k_ok,MID(IF(INDEX(VCalc!$C$5:$W$25,11,1+5*(k_model-1)+2)<>""," · "&INDEX(VCalc!$C$5:$W$25,11,1+5*(k_model-1)+2),"")&IF(INDEX(VCalc!$C$5:$W$25,11,1+5*(k_model-1)+3)<>""," · "&INDEX(VCalc!$C$5:$W$25,11,1+5*(k_model-1)+3),"")&IF(INDEX(VCalc!$C$5:$W$25,11,1+5*(k_model-1)+4)<>""," · "&INDEX(VCalc!$C$5:$W$25,11,1+5*(k_model-1)+4),""),4,500),"") | G17: =IF(k_m1=11,"● LT1","") | H17: =IF(k_m2=11,"● LT2","")
A18: Exp-Dmax | B18: LT2 | C18: =IF(AND(k_ok,ISNUMBER(INDEX(VCalc!$C$5:$W$25,12,1+5*(k_model-1)+0))),ROUND(INDEX(VCalc!$C$5:$W$25,12,1+5*(k_model-1)+0),k_xd),"–") | D18: =IF(AND(k_ok,ISNUMBER(INDEX(VCalc!$C$5:$W$25,12,1+5*(k_model-1)+0))),ROUND(INDEX(VCalc!$C$5:$W$25,12,1+5*(k_model-1)+1),2),"–") | E18: =IF(AND(k_ok,ISNUMBER(INDEX(VCalc!$C$5:$W$25,12,1+5*(k_model-1)+0))),IFERROR(ROUND(IF(k_hrok,k_h0+k_h1*(INDEX(VCalc!$C$5:$W$25,12,1+5*(k_model-1)+0))+k_h2*(INDEX(VCalc!$C$5:$W$25,12,1+5*(k_model-1)+0))^2,""),0),"–"),"–") | F18: =IF(k_ok,MID(IF(INDEX(VCalc!$C$5:$W$25,12,1+5*(k_model-1)+2)<>""," · "&INDEX(VCalc!$C$5:$W$25,12,1+5*(k_model-1)+2),"")&IF(INDEX(VCalc!$C$5:$W$25,12,1+5*(k_model-1)+3)<>""," · "&INDEX(VCalc!$C$5:$W$25,12,1+5*(k_model-1)+3),"")&IF(INDEX(VCalc!$C$5:$W$25,12,1+5*(k_model-1)+4)<>""," · "&INDEX(VCalc!$C$5:$W$25,12,1+5*(k_model-1)+4),""),4,500),"") | G18: =IF(k_m1=12,"● LT1","") | H18: =IF(k_m2=12,"● LT2","")
A19: Dickhuth (LEmin + 1,5) | B19: individuelle obere Schwelle | C19: =IF(AND(k_ok,ISNUMBER(INDEX(VCalc!$C$5:$W$25,13,1+5*(k_model-1)+0))),ROUND(INDEX(VCalc!$C$5:$W$25,13,1+5*(k_model-1)+0),k_xd),"–") | D19: =IF(AND(k_ok,ISNUMBER(INDEX(VCalc!$C$5:$W$25,13,1+5*(k_model-1)+0))),ROUND(INDEX(VCalc!$C$5:$W$25,13,1+5*(k_model-1)+1),2),"–") | E19: =IF(AND(k_ok,ISNUMBER(INDEX(VCalc!$C$5:$W$25,13,1+5*(k_model-1)+0))),IFERROR(ROUND(IF(k_hrok,k_h0+k_h1*(INDEX(VCalc!$C$5:$W$25,13,1+5*(k_model-1)+0))+k_h2*(INDEX(VCalc!$C$5:$W$25,13,1+5*(k_model-1)+0))^2,""),0),"–"),"–") | F19: =IF(k_ok,MID(IF(INDEX(VCalc!$C$5:$W$25,13,1+5*(k_model-1)+2)<>""," · "&INDEX(VCalc!$C$5:$W$25,13,1+5*(k_model-1)+2),"")&IF(INDEX(VCalc!$C$5:$W$25,13,1+5*(k_model-1)+3)<>""," · "&INDEX(VCalc!$C$5:$W$25,13,1+5*(k_model-1)+3),"")&IF(INDEX(VCalc!$C$5:$W$25,13,1+5*(k_model-1)+4)<>""," · "&INDEX(VCalc!$C$5:$W$25,13,1+5*(k_model-1)+4),""),4,500),"") | G19: =IF(k_m1=13,"● LT1","") | H19: =IF(k_m2=13,"● LT2","")
A20: Baseline + 1,0 mmol/L | B20: Übergangsbereich | C20: =IF(AND(k_ok,ISNUMBER(INDEX(VCalc!$C$5:$W$25,14,1+5*(k_model-1)+0))),ROUND(INDEX(VCalc!$C$5:$W$25,14,1+5*(k_model-1)+0),k_xd),"–") | D20: =IF(AND(k_ok,ISNUMBER(INDEX(VCalc!$C$5:$W$25,14,1+5*(k_model-1)+0))),ROUND(INDEX(VCalc!$C$5:$W$25,14,1+5*(k_model-1)+1),2),"–") | E20: =IF(AND(k_ok,ISNUMBER(INDEX(VCalc!$C$5:$W$25,14,1+5*(k_model-1)+0))),IFERROR(ROUND(IF(k_hrok,k_h0+k_h1*(INDEX(VCalc!$C$5:$W$25,14,1+5*(k_model-1)+0))+k_h2*(INDEX(VCalc!$C$5:$W$25,14,1+5*(k_model-1)+0))^2,""),0),"–"),"–") | F20: =IF(k_ok,MID(IF(INDEX(VCalc!$C$5:$W$25,14,1+5*(k_model-1)+2)<>""," · "&INDEX(VCalc!$C$5:$W$25,14,1+5*(k_model-1)+2),"")&IF(INDEX(VCalc!$C$5:$W$25,14,1+5*(k_model-1)+3)<>""," · "&INDEX(VCalc!$C$5:$W$25,14,1+5*(k_model-1)+3),"")&IF(INDEX(VCalc!$C$5:$W$25,14,1+5*(k_model-1)+4)<>""," · "&INDEX(VCalc!$C$5:$W$25,14,1+5*(k_model-1)+4),""),4,500),"") | G20: =IF(k_m1=14,"● LT1","") | H20: =IF(k_m2=14,"● LT2","")
A21: Baseline + 1,5 mmol/L | B21: obere Schwelle (Simon-Typ) | C21: =IF(AND(k_ok,ISNUMBER(INDEX(VCalc!$C$5:$W$25,15,1+5*(k_model-1)+0))),ROUND(INDEX(VCalc!$C$5:$W$25,15,1+5*(k_model-1)+0),k_xd),"–") | D21: =IF(AND(k_ok,ISNUMBER(INDEX(VCalc!$C$5:$W$25,15,1+5*(k_model-1)+0))),ROUND(INDEX(VCalc!$C$5:$W$25,15,1+5*(k_model-1)+1),2),"–") | E21: =IF(AND(k_ok,ISNUMBER(INDEX(VCalc!$C$5:$W$25,15,1+5*(k_model-1)+0))),IFERROR(ROUND(IF(k_hrok,k_h0+k_h1*(INDEX(VCalc!$C$5:$W$25,15,1+5*(k_model-1)+0))+k_h2*(INDEX(VCalc!$C$5:$W$25,15,1+5*(k_model-1)+0))^2,""),0),"–"),"–") | F21: =IF(k_ok,MID(IF(INDEX(VCalc!$C$5:$W$25,15,1+5*(k_model-1)+2)<>""," · "&INDEX(VCalc!$C$5:$W$25,15,1+5*(k_model-1)+2),"")&IF(INDEX(VCalc!$C$5:$W$25,15,1+5*(k_model-1)+3)<>""," · "&INDEX(VCalc!$C$5:$W$25,15,1+5*(k_model-1)+3),"")&IF(INDEX(VCalc!$C$5:$W$25,15,1+5*(k_model-1)+4)<>""," · "&INDEX(VCalc!$C$5:$W$25,15,1+5*(k_model-1)+4),""),4,500),"") | G21: =IF(k_m1=15,"● LT1","") | H21: =IF(k_m2=15,"● LT2","")
A22: Fixe, diskrete und historische Verfahren
A23: fix 3,0 mmol/L | B23: fixer Anker | C23: =IF(AND(k_ok,ISNUMBER(INDEX(VCalc!$C$5:$W$25,16,1+5*(k_model-1)+0))),ROUND(INDEX(VCalc!$C$5:$W$25,16,1+5*(k_model-1)+0),k_xd),"–") | D23: =IF(AND(k_ok,ISNUMBER(INDEX(VCalc!$C$5:$W$25,16,1+5*(k_model-1)+0))),ROUND(INDEX(VCalc!$C$5:$W$25,16,1+5*(k_model-1)+1),2),"–") | E23: =IF(AND(k_ok,ISNUMBER(INDEX(VCalc!$C$5:$W$25,16,1+5*(k_model-1)+0))),IFERROR(ROUND(IF(k_hrok,k_h0+k_h1*(INDEX(VCalc!$C$5:$W$25,16,1+5*(k_model-1)+0))+k_h2*(INDEX(VCalc!$C$5:$W$25,16,1+5*(k_model-1)+0))^2,""),0),"–"),"–") | F23: =IF(k_ok,MID(IF(INDEX(VCalc!$C$5:$W$25,16,1+5*(k_model-1)+2)<>""," · "&INDEX(VCalc!$C$5:$W$25,16,1+5*(k_model-1)+2),"")&IF(INDEX(VCalc!$C$5:$W$25,16,1+5*(k_model-1)+3)<>""," · "&INDEX(VCalc!$C$5:$W$25,16,1+5*(k_model-1)+3),"")&IF(INDEX(VCalc!$C$5:$W$25,16,1+5*(k_model-1)+4)<>""," · "&INDEX(VCalc!$C$5:$W$25,16,1+5*(k_model-1)+4),""),4,500),"") | G23: =IF(k_m1=16,"● LT1","") | H23: =IF(k_m2=16,"● LT2","")
A24: fix 3,5 mmol/L | B24: fixer Anker | C24: =IF(AND(k_ok,ISNUMBER(INDEX(VCalc!$C$5:$W$25,17,1+5*(k_model-1)+0))),ROUND(INDEX(VCalc!$C$5:$W$25,17,1+5*(k_model-1)+0),k_xd),"–") | D24: =IF(AND(k_ok,ISNUMBER(INDEX(VCalc!$C$5:$W$25,17,1+5*(k_model-1)+0))),ROUND(INDEX(VCalc!$C$5:$W$25,17,1+5*(k_model-1)+1),2),"–") | E24: =IF(AND(k_ok,ISNUMBER(INDEX(VCalc!$C$5:$W$25,17,1+5*(k_model-1)+0))),IFERROR(ROUND(IF(k_hrok,k_h0+k_h1*(INDEX(VCalc!$C$5:$W$25,17,1+5*(k_model-1)+0))+k_h2*(INDEX(VCalc!$C$5:$W$25,17,1+5*(k_model-1)+0))^2,""),0),"–"),"–") | F24: =IF(k_ok,MID(IF(INDEX(VCalc!$C$5:$W$25,17,1+5*(k_model-1)+2)<>""," · "&INDEX(VCalc!$C$5:$W$25,17,1+5*(k_model-1)+2),"")&IF(INDEX(VCalc!$C$5:$W$25,17,1+5*(k_model-1)+3)<>""," · "&INDEX(VCalc!$C$5:$W$25,17,1+5*(k_model-1)+3),"")&IF(INDEX(VCalc!$C$5:$W$25,17,1+5*(k_model-1)+4)<>""," · "&INDEX(VCalc!$C$5:$W$25,17,1+5*(k_model-1)+4),""),4,500),"") | G24: =IF(k_m1=17,"● LT1","") | H24: =IF(k_m2=17,"● LT2","")
A25: fix 4,0 mmol/L (OBLA) | B25: obere fixe Schwelle, ≠ MLSS | C25: =IF(AND(k_ok,ISNUMBER(INDEX(VCalc!$C$5:$W$25,18,1+5*(k_model-1)+0))),ROUND(INDEX(VCalc!$C$5:$W$25,18,1+5*(k_model-1)+0),k_xd),"–") | D25: =IF(AND(k_ok,ISNUMBER(INDEX(VCalc!$C$5:$W$25,18,1+5*(k_model-1)+0))),ROUND(INDEX(VCalc!$C$5:$W$25,18,1+5*(k_model-1)+1),2),"–") | E25: =IF(AND(k_ok,ISNUMBER(INDEX(VCalc!$C$5:$W$25,18,1+5*(k_model-1)+0))),IFERROR(ROUND(IF(k_hrok,k_h0+k_h1*(INDEX(VCalc!$C$5:$W$25,18,1+5*(k_model-1)+0))+k_h2*(INDEX(VCalc!$C$5:$W$25,18,1+5*(k_model-1)+0))^2,""),0),"–"),"–") | F25: =IF(k_ok,MID(IF(INDEX(VCalc!$C$5:$W$25,18,1+5*(k_model-1)+2)<>""," · "&INDEX(VCalc!$C$5:$W$25,18,1+5*(k_model-1)+2),"")&IF(INDEX(VCalc!$C$5:$W$25,18,1+5*(k_model-1)+3)<>""," · "&INDEX(VCalc!$C$5:$W$25,18,1+5*(k_model-1)+3),"")&IF(INDEX(VCalc!$C$5:$W$25,18,1+5*(k_model-1)+4)<>""," · "&INDEX(VCalc!$C$5:$W$25,18,1+5*(k_model-1)+4),""),4,500),"") | G25: =IF(k_m1=18,"● LT1","") | H25: =IF(k_m2=18,"● LT2","")
A26: Baldari-Guidetti | B26: MLSS-Näherung | C26: =IF(AND(k_ok,ISNUMBER(INDEX(VCalc!$C$5:$W$25,19,1+5*(k_model-1)+0))),ROUND(INDEX(VCalc!$C$5:$W$25,19,1+5*(k_model-1)+0),k_xd),"–") | D26: =IF(AND(k_ok,ISNUMBER(INDEX(VCalc!$C$5:$W$25,19,1+5*(k_model-1)+0))),ROUND(INDEX(VCalc!$C$5:$W$25,19,1+5*(k_model-1)+1),2),"–") | E26: =IF(AND(k_ok,ISNUMBER(INDEX(VCalc!$C$5:$W$25,19,1+5*(k_model-1)+0))),IFERROR(ROUND(IF(k_hrok,k_h0+k_h1*(INDEX(VCalc!$C$5:$W$25,19,1+5*(k_model-1)+0))+k_h2*(INDEX(VCalc!$C$5:$W$25,19,1+5*(k_model-1)+0))^2,""),0),"–"),"–") | F26: =IF(k_ok,MID(IF(INDEX(VCalc!$C$5:$W$25,19,1+5*(k_model-1)+2)<>""," · "&INDEX(VCalc!$C$5:$W$25,19,1+5*(k_model-1)+2),"")&IF(INDEX(VCalc!$C$5:$W$25,19,1+5*(k_model-1)+3)<>""," · "&INDEX(VCalc!$C$5:$W$25,19,1+5*(k_model-1)+3),"")&IF(INDEX(VCalc!$C$5:$W$25,19,1+5*(k_model-1)+4)<>""," · "&INDEX(VCalc!$C$5:$W$25,19,1+5*(k_model-1)+4),""),4,500),"") | G26: =IF(k_m1=19,"● LT1","") | H26: =IF(k_m2=19,"● LT2","")
A27: Keul (Tangente 51°) | B27: historisch | C27: =IF(AND(k_ok,ISNUMBER(INDEX(VCalc!$C$5:$W$25,20,1+5*(k_model-1)+0))),ROUND(INDEX(VCalc!$C$5:$W$25,20,1+5*(k_model-1)+0),k_xd),"–") | D27: =IF(AND(k_ok,ISNUMBER(INDEX(VCalc!$C$5:$W$25,20,1+5*(k_model-1)+0))),ROUND(INDEX(VCalc!$C$5:$W$25,20,1+5*(k_model-1)+1),2),"–") | E27: =IF(AND(k_ok,ISNUMBER(INDEX(VCalc!$C$5:$W$25,20,1+5*(k_model-1)+0))),IFERROR(ROUND(IF(k_hrok,k_h0+k_h1*(INDEX(VCalc!$C$5:$W$25,20,1+5*(k_model-1)+0))+k_h2*(INDEX(VCalc!$C$5:$W$25,20,1+5*(k_model-1)+0))^2,""),0),"–"),"–") | F27: =IF(k_ok,MID(IF(INDEX(VCalc!$C$5:$W$25,20,1+5*(k_model-1)+2)<>""," · "&INDEX(VCalc!$C$5:$W$25,20,1+5*(k_model-1)+2),"")&IF(INDEX(VCalc!$C$5:$W$25,20,1+5*(k_model-1)+3)<>""," · "&INDEX(VCalc!$C$5:$W$25,20,1+5*(k_model-1)+3),"")&IF(INDEX(VCalc!$C$5:$W$25,20,1+5*(k_model-1)+4)<>""," · "&INDEX(VCalc!$C$5:$W$25,20,1+5*(k_model-1)+4),""),4,500),"") | G27: =IF(k_m1=20,"● LT1","") | H27: =IF(k_m2=20,"● LT2","")
A28: Laktatminimum (Tegtbur) | B28: nur bei LMT-Protokoll | C28: =IF(AND(k_ok,ISNUMBER(INDEX(VCalc!$C$5:$W$25,21,1+5*(k_model-1)+0))),ROUND(INDEX(VCalc!$C$5:$W$25,21,1+5*(k_model-1)+0),k_xd),"–") | D28: =IF(AND(k_ok,ISNUMBER(INDEX(VCalc!$C$5:$W$25,21,1+5*(k_model-1)+0))),ROUND(INDEX(VCalc!$C$5:$W$25,21,1+5*(k_model-1)+1),2),"–") | E28: =IF(AND(k_ok,ISNUMBER(INDEX(VCalc!$C$5:$W$25,21,1+5*(k_model-1)+0))),IFERROR(ROUND(IF(k_hrok,k_h0+k_h1*(INDEX(VCalc!$C$5:$W$25,21,1+5*(k_model-1)+0))+k_h2*(INDEX(VCalc!$C$5:$W$25,21,1+5*(k_model-1)+0))^2,""),0),"–"),"–") | F28: =IF(k_ok,MID(IF(INDEX(VCalc!$C$5:$W$25,21,1+5*(k_model-1)+2)<>""," · "&INDEX(VCalc!$C$5:$W$25,21,1+5*(k_model-1)+2),"")&IF(INDEX(VCalc!$C$5:$W$25,21,1+5*(k_model-1)+3)<>""," · "&INDEX(VCalc!$C$5:$W$25,21,1+5*(k_model-1)+3),"")&IF(INDEX(VCalc!$C$5:$W$25,21,1+5*(k_model-1)+4)<>""," · "&INDEX(VCalc!$C$5:$W$25,21,1+5*(k_model-1)+4),""),4,500),"") | G28: =IF(k_m1=21,"● LT1","") | H28: =IF(k_m2=21,"● LT2","")
A31: Modellvergleich am selben Datensatz
A32: Wie stark sich LT1 und LT2 allein durch das Kurvenmodell verschieben. Ein höheres R² macht ein Modell nicht besser.
A33: Modell | B33: Parameter | C33: R² | D33: RMSE | E33: ="LT1 · "&Eingabe!$I$5 | F33: ="LT2 · "&Eingabe!$I$6 | G33: Δ LT2
A34: ="Polynom 2. Grades"&IF(AND(Calc!$B$82,Calc!$G$82)," (exakt)","")&IF(k_model=1," ◄ gewählt","") | B34: =IF(Calc!$B$82,Calc!$C$82,"nicht anpassbar") | C34: =IF(AND(k_ok,Calc!$B$82),ROUND(Calc!$E$82,4),"–") | D34: =IF(AND(k_ok,Calc!$B$82),ROUND(Calc!$F$82,3),"–") | E34: =IF(AND(k_ok,Calc!$B$82,ISNUMBER(INDEX(VCalc!$C$5:$W$25,k_m1,1))),ROUND(INDEX(VCalc!$C$5:$W$25,k_m1,1),k_xd),"–") | F34: =IF(AND(k_ok,Calc!$B$82,ISNUMBER(INDEX(VCalc!$C$5:$W$25,k_m2,1))),ROUND(INDEX(VCalc!$C$5:$W$25,k_m2,1),k_xd),"–") | G34: =IF(AND(k_ok,Calc!$B$82,ISNUMBER(INDEX(VCalc!$C$5:$W$25,k_m2,1)),ISNUMBER(INDEX(VCalc!$C$5:$W$25,k_m2,1+5*(k_model-1)))),IF(k_model=1,"Referenz",IF(INDEX(VCalc!$C$5:$W$25,k_m2,1)-INDEX(VCalc!$C$5:$W$25,k_m2,1+5*(k_model-1))>=0,"+","")&FIXED(INDEX(VCalc!$C$5:$W$25,k_m2,1)-INDEX(VCalc!$C$5:$W$25,k_m2,1+5*(k_model-1)),k_xd,TRUE)),"–")
A35: ="Polynom 3. Grades"&IF(AND(Calc!$B$83,Calc!$G$83)," (exakt)","")&IF(k_model=2," ◄ gewählt","") | B35: =IF(Calc!$B$83,Calc!$C$83,"nicht anpassbar") | C35: =IF(AND(k_ok,Calc!$B$83),ROUND(Calc!$E$83,4),"–") | D35: =IF(AND(k_ok,Calc!$B$83),ROUND(Calc!$F$83,3),"–") | E35: =IF(AND(k_ok,Calc!$B$83,ISNUMBER(INDEX(VCalc!$C$5:$W$25,k_m1,6))),ROUND(INDEX(VCalc!$C$5:$W$25,k_m1,6),k_xd),"–") | F35: =IF(AND(k_ok,Calc!$B$83,ISNUMBER(INDEX(VCalc!$C$5:$W$25,k_m2,6))),ROUND(INDEX(VCalc!$C$5:$W$25,k_m2,6),k_xd),"–") | G35: =IF(AND(k_ok,Calc!$B$83,ISNUMBER(INDEX(VCalc!$C$5:$W$25,k_m2,6)),ISNUMBER(INDEX(VCalc!$C$5:$W$25,k_m2,1+5*(k_model-1)))),IF(k_model=2,"Referenz",IF(INDEX(VCalc!$C$5:$W$25,k_m2,6)-INDEX(VCalc!$C$5:$W$25,k_m2,1+5*(k_model-1))>=0,"+","")&FIXED(INDEX(VCalc!$C$5:$W$25,k_m2,6)-INDEX(VCalc!$C$5:$W$25,k_m2,1+5*(k_model-1)),k_xd,TRUE)),"–")
A36: ="Polynom 4. Grades"&IF(AND(Calc!$B$84,Calc!$G$84)," (exakt)","")&IF(k_model=3," ◄ gewählt","") | B36: =IF(Calc!$B$84,Calc!$C$84,"nicht anpassbar") | C36: =IF(AND(k_ok,Calc!$B$84),ROUND(Calc!$E$84,4),"–") | D36: =IF(AND(k_ok,Calc!$B$84),ROUND(Calc!$F$84,3),"–") | E36: =IF(AND(k_ok,Calc!$B$84,ISNUMBER(INDEX(VCalc!$C$5:$W$25,k_m1,11))),ROUND(INDEX(VCalc!$C$5:$W$25,k_m1,11),k_xd),"–") | F36: =IF(AND(k_ok,Calc!$B$84,ISNUMBER(INDEX(VCalc!$C$5:$W$25,k_m2,11))),ROUND(INDEX(VCalc!$C$5:$W$25,k_m2,11),k_xd),"–") | G36: =IF(AND(k_ok,Calc!$B$84,ISNUMBER(INDEX(VCalc!$C$5:$W$25,k_m2,11)),ISNUMBER(INDEX(VCalc!$C$5:$W$25,k_m2,1+5*(k_model-1)))),IF(k_model=3,"Referenz",IF(INDEX(VCalc!$C$5:$W$25,k_m2,11)-INDEX(VCalc!$C$5:$W$25,k_m2,1+5*(k_model-1))>=0,"+","")&FIXED(INDEX(VCalc!$C$5:$W$25,k_m2,11)-INDEX(VCalc!$C$5:$W$25,k_m2,1+5*(k_model-1)),k_xd,TRUE)),"–")
A37: ="Exponentiell"&IF(AND(Calc!$B$85,Calc!$G$85)," (exakt)","")&IF(k_model=4," ◄ gewählt","") | B37: =IF(Calc!$B$85,Calc!$C$85,"nicht anpassbar") | C37: =IF(AND(k_ok,Calc!$B$85),ROUND(Calc!$E$85,4),"–") | D37: =IF(AND(k_ok,Calc!$B$85),ROUND(Calc!$F$85,3),"–") | E37: =IF(AND(k_ok,Calc!$B$85,ISNUMBER(INDEX(VCalc!$C$5:$W$25,k_m1,16))),ROUND(INDEX(VCalc!$C$5:$W$25,k_m1,16),k_xd),"–") | F37: =IF(AND(k_ok,Calc!$B$85,ISNUMBER(INDEX(VCalc!$C$5:$W$25,k_m2,16))),ROUND(INDEX(VCalc!$C$5:$W$25,k_m2,16),k_xd),"–") | G37: =IF(AND(k_ok,Calc!$B$85,ISNUMBER(INDEX(VCalc!$C$5:$W$25,k_m2,16)),ISNUMBER(INDEX(VCalc!$C$5:$W$25,k_m2,1+5*(k_model-1)))),IF(k_model=4,"Referenz",IF(INDEX(VCalc!$C$5:$W$25,k_m2,16)-INDEX(VCalc!$C$5:$W$25,k_m2,1+5*(k_model-1))>=0,"+","")&FIXED(INDEX(VCalc!$C$5:$W$25,k_m2,16)-INDEX(VCalc!$C$5:$W$25,k_m2,1+5*(k_model-1)),k_xd,TRUE)),"–")
A39: =IF(k_ok,"Koeffizienten des gewählten Modells (x in "&k_unit&"): "&k_eq,"")
A40: =IF(k_ok,"Güte gewählt: R² "&FIXED(N(k_r2),4,TRUE)&" · RMSE "&FIXED(k_rmse,3,TRUE)&" mmol/L · n = "&k_n&IF(k_gok," · Hilfsgeraden-RMSE "&FIXED(k_grmse,3,TRUE)&" mmol/L"&IF(Guide!$B$6," (optimale Knoten)"," (Knoten an LT1/LT2) · Regressions-Optimum bei "&IF(k_3ok,FIXED(k_3k1,k_xd,TRUE)&" / "&FIXED(k_3k2,k_xd,TRUE),"–")),""),"")

Sheet Diagramme
A1: Weitere Darstellungen
A2: Laktatäquivalent: Das Minimum markiert den Übergang aus dem aeroben Grundbereich (Grundlage des Dickhuth-Verfahrens: LEmin + 1,5 mmol/L). Log-Log: ln Laktat gegen ln Belastung, zwei Regressionsgeraden, Schnittpunkt = Log-Log-Breakpoint.
A24: =IF(k_llok,"Log-Log-Breakpoint bei "&FIXED(k_llx,k_xd,TRUE)&" "&k_unit&" (Segmente "&k_llk&" + "&(k_n-k_llk)&" Punkte)","Log-Log-Breakpoint nicht bestimmbar")
A25: =IF(k_ok,"LEmin bei "&FIXED(INDEX(VCalc!$C$35:$F$35,k_model),k_xd,TRUE)&" "&k_unit&" ("&FIXED(INDEX(VCalc!$C$36:$F$36,k_model),2,TRUE)&" mmol/L)","")
A27: Glukose zu Belastung
A28: =IF(AND(k_gluOn,k_ng>=2),k_ng&" Werte · erste → letzte Stufe "&IF(INDEX(Calc!$AL$3:$AL$22,k_ng)-Calc!$AL$3>=0,"+","")&FIXED(INDEX(Calc!$AL$3:$AL$22,k_ng)-Calc!$AL$3,k_gd,TRUE)&" "&k_gluU&" · Minimum "&FIXED(MIN(OFFSET(Calc!$AL$3,0,0,k_ng,1)),k_gd,TRUE)&" bei "&FIXED(INDEX(Calc!$AK$3:$AK$22,MATCH(MIN(OFFSET(Calc!$AL$3,0,0,k_ng,1)),OFFSET(Calc!$AL$3,0,0,k_ng,1),0)),k_xd,TRUE)&" "&k_unit,"Glukose-Auswertung: im Blatt „Eingabe“ „Glukose je Stufe erfassen = Ja“ wählen und mind. 2 Werte eintragen.")

Sheet Bericht
A1: =IF(Eingabe!$B$12<>"",Eingabe!$B$12,"") | H1: Laktatdiagnostik
A2: =IF(Eingabe!$B$13<>"",Eingabe!$B$13,"")
A3: Ergebnisse der Leistungsdiagnostik
A5: Name | B5: =Eingabe!$B$4 | E5: Testleitung | F5: =Eingabe!$B$10
A6: Geburtsdatum | B6: =IF(ISNUMBER(Eingabe!$B$5),TEXT(Eingabe!$B$5,"DD.MM.YYYY")&IF(ISNUMBER(k_age)," ("&FIXED(k_age,1,TRUE)&" Jahre)",""),Eingabe!$B$5&"") | E6: Untersuchung | F6: =IF(k_run,"Laufbandergometrie","Fahrradergometrie")
A7: Größe | B7: =IF(ISNUMBER(Eingabe!$B$7),Eingabe!$B$7&" cm","–") | E7: Stufen | F7: =IF(ISNUMBER(k_dur),FIXED(k_dur,1,TRUE),"–")&" min, "&IF(Eingabe!$E$5="","–",Eingabe!$E$5)
A8: Masse | B8: =IF(ISNUMBER(Eingabe!$B$8),Eingabe!$B$8&" kg","–") | E8: Probe | F8: =Eingabe!$E$6&", "&Eingabe!$E$7
A9: Testdatum | B9: =IF(ISNUMBER(Eingabe!$B$6),TEXT(Eingabe!$B$6,"DD.MM.YYYY"),Eingabe!$B$6&"") | E9: Analysator | F9: =IF(Eingabe!$E$8="","–",Eingabe!$E$8)
A10: Bemerkung | B10: =Eingabe!$B$11&""
A11: Ruhewerte | B11: ="Laktat "&IF(ISNUMBER(k_rest),FIXED(k_rest,2,TRUE),"–")&" mmol/L Glukose "&IF(ISNUMBER(Eingabe!$E$10),FIXED(Eingabe!$E$10,k_gd,TRUE),"–")&" "&k_gluU
A13: Gemessene Werte
A14: Zeit [min] | B14: ="Belastung ["&k_unit&"]" | C14: Pace [min/km] | D14: Laktat [mmol/L] | E14: HF [1/min] | F14: =IF(k_gluOn,"Glukose ["&k_gluU&"]","")
A15: =IF(1<=k_n,INDEX(Eingabe!$B$17:$B$36,Calc!$H$3)&"","") | B15: =IF(1<=k_n,ROUND(Calc!$G$3,k_xd),"") | C15: =IF(AND(k_run,1<=k_n),IF(N(Calc!$G$3)>0,INT(ROUND(3600/(Calc!$G$3),0)/60)&":"&TEXT(MOD(ROUND(3600/(Calc!$G$3),0),60),"00"),"–"),"") | D15: =IF(1<=k_n,Calc!$I$3,"") | E15: =IF(1<=k_n,IF(ISNUMBER(Calc!$J$3),Calc!$J$3,"–"),"") | F15: =IF(AND(k_gluOn,1<=k_n),IF(ISNUMBER(INDEX(Eingabe!$F$17:$F$36,Calc!$H$3)),INDEX(Eingabe!$F$17:$F$36,Calc!$H$3),"–"),"")
A16: =IF(2<=k_n,INDEX(Eingabe!$B$17:$B$36,Calc!$H$4)&"","") | B16: =IF(2<=k_n,ROUND(Calc!$G$4,k_xd),"") | C16: =IF(AND(k_run,2<=k_n),IF(N(Calc!$G$4)>0,INT(ROUND(3600/(Calc!$G$4),0)/60)&":"&TEXT(MOD(ROUND(3600/(Calc!$G$4),0),60),"00"),"–"),"") | D16: =IF(2<=k_n,Calc!$I$4,"") | E16: =IF(2<=k_n,IF(ISNUMBER(Calc!$J$4),Calc!$J$4,"–"),"") | F16: =IF(AND(k_gluOn,2<=k_n),IF(ISNUMBER(INDEX(Eingabe!$F$17:$F$36,Calc!$H$4)),INDEX(Eingabe!$F$17:$F$36,Calc!$H$4),"–"),"")
A17: =IF(3<=k_n,INDEX(Eingabe!$B$17:$B$36,Calc!$H$5)&"","") | B17: =IF(3<=k_n,ROUND(Calc!$G$5,k_xd),"") | C17: =IF(AND(k_run,3<=k_n),IF(N(Calc!$G$5)>0,INT(ROUND(3600/(Calc!$G$5),0)/60)&":"&TEXT(MOD(ROUND(3600/(Calc!$G$5),0),60),"00"),"–"),"") | D17: =IF(3<=k_n,Calc!$I$5,"") | E17: =IF(3<=k_n,IF(ISNUMBER(Calc!$J$5),Calc!$J$5,"–"),"") | F17: =IF(AND(k_gluOn,3<=k_n),IF(ISNUMBER(INDEX(Eingabe!$F$17:$F$36,Calc!$H$5)),INDEX(Eingabe!$F$17:$F$36,Calc!$H$5),"–"),"")
A18: =IF(4<=k_n,INDEX(Eingabe!$B$17:$B$36,Calc!$H$6)&"","") | B18: =IF(4<=k_n,ROUND(Calc!$G$6,k_xd),"") | C18: =IF(AND(k_run,4<=k_n),IF(N(Calc!$G$6)>0,INT(ROUND(3600/(Calc!$G$6),0)/60)&":"&TEXT(MOD(ROUND(3600/(Calc!$G$6),0),60),"00"),"–"),"") | D18: =IF(4<=k_n,Calc!$I$6,"") | E18: =IF(4<=k_n,IF(ISNUMBER(Calc!$J$6),Calc!$J$6,"–"),"") | F18: =IF(AND(k_gluOn,4<=k_n),IF(ISNUMBER(INDEX(Eingabe!$F$17:$F$36,Calc!$H$6)),INDEX(Eingabe!$F$17:$F$36,Calc!$H$6),"–"),"")
A19: =IF(5<=k_n,INDEX(Eingabe!$B$17:$B$36,Calc!$H$7)&"","") | B19: =IF(5<=k_n,ROUND(Calc!$G$7,k_xd),"") | C19: =IF(AND(k_run,5<=k_n),IF(N(Calc!$G$7)>0,INT(ROUND(3600/(Calc!$G$7),0)/60)&":"&TEXT(MOD(ROUND(3600/(Calc!$G$7),0),60),"00"),"–"),"") | D19: =IF(5<=k_n,Calc!$I$7,"") | E19: =IF(5<=k_n,IF(ISNUMBER(Calc!$J$7),Calc!$J$7,"–"),"") | F19: =IF(AND(k_gluOn,5<=k_n),IF(ISNUMBER(INDEX(Eingabe!$F$17:$F$36,Calc!$H$7)),INDEX(Eingabe!$F$17:$F$36,Calc!$H$7),"–"),"")
A20: =IF(6<=k_n,INDEX(Eingabe!$B$17:$B$36,Calc!$H$8)&"","") | B20: =IF(6<=k_n,ROUND(Calc!$G$8,k_xd),"") | C20: =IF(AND(k_run,6<=k_n),IF(N(Calc!$G$8)>0,INT(ROUND(3600/(Calc!$G$8),0)/60)&":"&TEXT(MOD(ROUND(3600/(Calc!$G$8),0),60),"00"),"–"),"") | D20: =IF(6<=k_n,Calc!$I$8,"") | E20: =IF(6<=k_n,IF(ISNUMBER(Calc!$J$8),Calc!$J$8,"–"),"") | F20: =IF(AND(k_gluOn,6<=k_n),IF(ISNUMBER(INDEX(Eingabe!$F$17:$F$36,Calc!$H$8)),INDEX(Eingabe!$F$17:$F$36,Calc!$H$8),"–"),"")
A21: =IF(7<=k_n,INDEX(Eingabe!$B$17:$B$36,Calc!$H$9)&"","") | B21: =IF(7<=k_n,ROUND(Calc!$G$9,k_xd),"") | C21: =IF(AND(k_run,7<=k_n),IF(N(Calc!$G$9)>0,INT(ROUND(3600/(Calc!$G$9),0)/60)&":"&TEXT(MOD(ROUND(3600/(Calc!$G$9),0),60),"00"),"–"),"") | D21: =IF(7<=k_n,Calc!$I$9,"") | E21: =IF(7<=k_n,IF(ISNUMBER(Calc!$J$9),Calc!$J$9,"–"),"") | F21: =IF(AND(k_gluOn,7<=k_n),IF(ISNUMBER(INDEX(Eingabe!$F$17:$F$36,Calc!$H$9)),INDEX(Eingabe!$F$17:$F$36,Calc!$H$9),"–"),"")
A22: =IF(8<=k_n,INDEX(Eingabe!$B$17:$B$36,Calc!$H$10)&"","") | B22: =IF(8<=k_n,ROUND(Calc!$G$10,k_xd),"") | C22: =IF(AND(k_run,8<=k_n),IF(N(Calc!$G$10)>0,INT(ROUND(3600/(Calc!$G$10),0)/60)&":"&TEXT(MOD(ROUND(3600/(Calc!$G$10),0),60),"00"),"–"),"") | D22: =IF(8<=k_n,Calc!$I$10,"") | E22: =IF(8<=k_n,IF(ISNUMBER(Calc!$J$10),Calc!$J$10,"–"),"") | F22: =IF(AND(k_gluOn,8<=k_n),IF(ISNUMBER(INDEX(Eingabe!$F$17:$F$36,Calc!$H$10)),INDEX(Eingabe!$F$17:$F$36,Calc!$H$10),"–"),"")
A23: =IF(9<=k_n,INDEX(Eingabe!$B$17:$B$36,Calc!$H$11)&"","") | B23: =IF(9<=k_n,ROUND(Calc!$G$11,k_xd),"") | C23: =IF(AND(k_run,9<=k_n),IF(N(Calc!$G$11)>0,INT(ROUND(3600/(Calc!$G$11),0)/60)&":"&TEXT(MOD(ROUND(3600/(Calc!$G$11),0),60),"00"),"–"),"") | D23: =IF(9<=k_n,Calc!$I$11,"") | E23: =IF(9<=k_n,IF(ISNUMBER(Calc!$J$11),Calc!$J$11,"–"),"") | F23: =IF(AND(k_gluOn,9<=k_n),IF(ISNUMBER(INDEX(Eingabe!$F$17:$F$36,Calc!$H$11)),INDEX(Eingabe!$F$17:$F$36,Calc!$H$11),"–"),"")
A24: =IF(10<=k_n,INDEX(Eingabe!$B$17:$B$36,Calc!$H$12)&"","") | B24: =IF(10<=k_n,ROUND(Calc!$G$12,k_xd),"") | C24: =IF(AND(k_run,10<=k_n),IF(N(Calc!$G$12)>0,INT(ROUND(3600/(Calc!$G$12),0)/60)&":"&TEXT(MOD(ROUND(3600/(Calc!$G$12),0),60),"00"),"–"),"") | D24: =IF(10<=k_n,Calc!$I$12,"") | E24: =IF(10<=k_n,IF(ISNUMBER(Calc!$J$12),Calc!$J$12,"–"),"") | F24: =IF(AND(k_gluOn,10<=k_n),IF(ISNUMBER(INDEX(Eingabe!$F$17:$F$36,Calc!$H$12)),INDEX(Eingabe!$F$17:$F$36,Calc!$H$12),"–"),"")
A25: =IF(11<=k_n,INDEX(Eingabe!$B$17:$B$36,Calc!$H$13)&"","") | B25: =IF(11<=k_n,ROUND(Calc!$G$13,k_xd),"") | C25: =IF(AND(k_run,11<=k_n),IF(N(Calc!$G$13)>0,INT(ROUND(3600/(Calc!$G$13),0)/60)&":"&TEXT(MOD(ROUND(3600/(Calc!$G$13),0),60),"00"),"–"),"") | D25: =IF(11<=k_n,Calc!$I$13,"") | E25: =IF(11<=k_n,IF(ISNUMBER(Calc!$J$13),Calc!$J$13,"–"),"") | F25: =IF(AND(k_gluOn,11<=k_n),IF(ISNUMBER(INDEX(Eingabe!$F$17:$F$36,Calc!$H$13)),INDEX(Eingabe!$F$17:$F$36,Calc!$H$13),"–"),"")
A26: =IF(12<=k_n,INDEX(Eingabe!$B$17:$B$36,Calc!$H$14)&"","") | B26: =IF(12<=k_n,ROUND(Calc!$G$14,k_xd),"") | C26: =IF(AND(k_run,12<=k_n),IF(N(Calc!$G$14)>0,INT(ROUND(3600/(Calc!$G$14),0)/60)&":"&TEXT(MOD(ROUND(3600/(Calc!$G$14),0),60),"00"),"–"),"") | D26: =IF(12<=k_n,Calc!$I$14,"") | E26: =IF(12<=k_n,IF(ISNUMBER(Calc!$J$14),Calc!$J$14,"–"),"") | F26: =IF(AND(k_gluOn,12<=k_n),IF(ISNUMBER(INDEX(Eingabe!$F$17:$F$36,Calc!$H$14)),INDEX(Eingabe!$F$17:$F$36,Calc!$H$14),"–"),"")
A27: =IF(13<=k_n,INDEX(Eingabe!$B$17:$B$36,Calc!$H$15)&"","") | B27: =IF(13<=k_n,ROUND(Calc!$G$15,k_xd),"") | C27: =IF(AND(k_run,13<=k_n),IF(N(Calc!$G$15)>0,INT(ROUND(3600/(Calc!$G$15),0)/60)&":"&TEXT(MOD(ROUND(3600/(Calc!$G$15),0),60),"00"),"–"),"") | D27: =IF(13<=k_n,Calc!$I$15,"") | E27: =IF(13<=k_n,IF(ISNUMBER(Calc!$J$15),Calc!$J$15,"–"),"") | F27: =IF(AND(k_gluOn,13<=k_n),IF(ISNUMBER(INDEX(Eingabe!$F$17:$F$36,Calc!$H$15)),INDEX(Eingabe!$F$17:$F$36,Calc!$H$15),"–"),"")
A28: =IF(14<=k_n,INDEX(Eingabe!$B$17:$B$36,Calc!$H$16)&"","") | B28: =IF(14<=k_n,ROUND(Calc!$G$16,k_xd),"") | C28: =IF(AND(k_run,14<=k_n),IF(N(Calc!$G$16)>0,INT(ROUND(3600/(Calc!$G$16),0)/60)&":"&TEXT(MOD(ROUND(3600/(Calc!$G$16),0),60),"00"),"–"),"") | D28: =IF(14<=k_n,Calc!$I$16,"") | E28: =IF(14<=k_n,IF(ISNUMBER(Calc!$J$16),Calc!$J$16,"–"),"") | F28: =IF(AND(k_gluOn,14<=k_n),IF(ISNUMBER(INDEX(Eingabe!$F$17:$F$36,Calc!$H$16)),INDEX(Eingabe!$F$17:$F$36,Calc!$H$16),"–"),"")
A29: =IF(15<=k_n,INDEX(Eingabe!$B$17:$B$36,Calc!$H$17)&"","") | B29: =IF(15<=k_n,ROUND(Calc!$G$17,k_xd),"") | C29: =IF(AND(k_run,15<=k_n),IF(N(Calc!$G$17)>0,INT(ROUND(3600/(Calc!$G$17),0)/60)&":"&TEXT(MOD(ROUND(3600/(Calc!$G$17),0),60),"00"),"–"),"") | D29: =IF(15<=k_n,Calc!$I$17,"") | E29: =IF(15<=k_n,IF(ISNUMBER(Calc!$J$17),Calc!$J$17,"–"),"") | F29: =IF(AND(k_gluOn,15<=k_n),IF(ISNUMBER(INDEX(Eingabe!$F$17:$F$36,Calc!$H$17)),INDEX(Eingabe!$F$17:$F$36,Calc!$H$17),"–"),"")
A30: =IF(16<=k_n,INDEX(Eingabe!$B$17:$B$36,Calc!$H$18)&"","") | B30: =IF(16<=k_n,ROUND(Calc!$G$18,k_xd),"") | C30: =IF(AND(k_run,16<=k_n),IF(N(Calc!$G$18)>0,INT(ROUND(3600/(Calc!$G$18),0)/60)&":"&TEXT(MOD(ROUND(3600/(Calc!$G$18),0),60),"00"),"–"),"") | D30: =IF(16<=k_n,Calc!$I$18,"") | E30: =IF(16<=k_n,IF(ISNUMBER(Calc!$J$18),Calc!$J$18,"–"),"") | F30: =IF(AND(k_gluOn,16<=k_n),IF(ISNUMBER(INDEX(Eingabe!$F$17:$F$36,Calc!$H$18)),INDEX(Eingabe!$F$17:$F$36,Calc!$H$18),"–"),"")
A31: =IF(17<=k_n,INDEX(Eingabe!$B$17:$B$36,Calc!$H$19)&"","") | B31: =IF(17<=k_n,ROUND(Calc!$G$19,k_xd),"") | C31: =IF(AND(k_run,17<=k_n),IF(N(Calc!$G$19)>0,INT(ROUND(3600/(Calc!$G$19),0)/60)&":"&TEXT(MOD(ROUND(3600/(Calc!$G$19),0),60),"00"),"–"),"") | D31: =IF(17<=k_n,Calc!$I$19,"") | E31: =IF(17<=k_n,IF(ISNUMBER(Calc!$J$19),Calc!$J$19,"–"),"") | F31: =IF(AND(k_gluOn,17<=k_n),IF(ISNUMBER(INDEX(Eingabe!$F$17:$F$36,Calc!$H$19)),INDEX(Eingabe!$F$17:$F$36,Calc!$H$19),"–"),"")
A32: =IF(18<=k_n,INDEX(Eingabe!$B$17:$B$36,Calc!$H$20)&"","") | B32: =IF(18<=k_n,ROUND(Calc!$G$20,k_xd),"") | C32: =IF(AND(k_run,18<=k_n),IF(N(Calc!$G$20)>0,INT(ROUND(3600/(Calc!$G$20),0)/60)&":"&TEXT(MOD(ROUND(3600/(Calc!$G$20),0),60),"00"),"–"),"") | D32: =IF(18<=k_n,Calc!$I$20,"") | E32: =IF(18<=k_n,IF(ISNUMBER(Calc!$J$20),Calc!$J$20,"–"),"") | F32: =IF(AND(k_gluOn,18<=k_n),IF(ISNUMBER(INDEX(Eingabe!$F$17:$F$36,Calc!$H$20)),INDEX(Eingabe!$F$17:$F$36,Calc!$H$20),"–"),"")
A33: =IF(19<=k_n,INDEX(Eingabe!$B$17:$B$36,Calc!$H$21)&"","") | B33: =IF(19<=k_n,ROUND(Calc!$G$21,k_xd),"") | C33: =IF(AND(k_run,19<=k_n),IF(N(Calc!$G$21)>0,INT(ROUND(3600/(Calc!$G$21),0)/60)&":"&TEXT(MOD(ROUND(3600/(Calc!$G$21),0),60),"00"),"–"),"") | D33: =IF(19<=k_n,Calc!$I$21,"") | E33: =IF(19<=k_n,IF(ISNUMBER(Calc!$J$21),Calc!$J$21,"–"),"") | F33: =IF(AND(k_gluOn,19<=k_n),IF(ISNUMBER(INDEX(Eingabe!$F$17:$F$36,Calc!$H$21)),INDEX(Eingabe!$F$17:$F$36,Calc!$H$21),"–"),"")
A34: =IF(20<=k_n,INDEX(Eingabe!$B$17:$B$36,Calc!$H$22)&"","") | B34: =IF(20<=k_n,ROUND(Calc!$G$22,k_xd),"") | C34: =IF(AND(k_run,20<=k_n),IF(N(Calc!$G$22)>0,INT(ROUND(3600/(Calc!$G$22),0)/60)&":"&TEXT(MOD(ROUND(3600/(Calc!$G$22),0),60),"00"),"–"),"") | D34: =IF(20<=k_n,Calc!$I$22,"") | E34: =IF(20<=k_n,IF(ISNUMBER(Calc!$J$22),Calc!$J$22,"–"),"") | F34: =IF(AND(k_gluOn,20<=k_n),IF(ISNUMBER(INDEX(Eingabe!$F$17:$F$36,Calc!$H$22)),INDEX(Eingabe!$F$17:$F$36,Calc!$H$22),"–"),"")
A36: Schwellen und Maximalwerte
B37: Verfahren | C37: ="Belastung ["&k_unit&"]" | D37: Pace [min/km] | E37: Laktat [mmol/L] | F37: HF [1/min] | G37: HF [%]
A38: LT1 | B38: =IF(k_ok,Eingabe!$I$5&IF(k_man1," (manuell)",""),"") | C38: =IF(AND(k_ok,ISNUMBER(k_x1)),ROUND(k_x1,k_xd),"–") | D38: =IF(AND(k_ok,k_run,ISNUMBER(k_x1)),IF(N(k_x1)>0,INT(ROUND(3600/(k_x1),0)/60)&":"&TEXT(MOD(ROUND(3600/(k_x1),0),60),"00"),"–"),"–") | E38: =IF(AND(k_ok,ISNUMBER(k_x1)),ROUND(k_la1,2),"–") | F38: =IF(AND(k_ok,ISNUMBER(k_x1)),IFERROR(ROUND(IF(k_hrok,k_h0+k_h1*(k_x1)+k_h2*(k_x1)^2,""),0),"–"),"–") | G38: =IF(AND(ISNUMBER(F38),ISNUMBER(k_hrmax)),ROUND(F38/k_hrmax*100,1),"–")
A39: LT2 | B39: =IF(k_ok,Eingabe!$I$6&IF(k_man2," (manuell)",""),"") | C39: =IF(AND(k_ok,ISNUMBER(k_x2)),ROUND(k_x2,k_xd),"–") | D39: =IF(AND(k_ok,k_run,ISNUMBER(k_x2)),IF(N(k_x2)>0,INT(ROUND(3600/(k_x2),0)/60)&":"&TEXT(MOD(ROUND(3600/(k_x2),0),60),"00"),"–"),"–") | E39: =IF(AND(k_ok,ISNUMBER(k_x2)),ROUND(k_la2,2),"–") | F39: =IF(AND(k_ok,ISNUMBER(k_x2)),IFERROR(ROUND(IF(k_hrok,k_h0+k_h1*(k_x2)+k_h2*(k_x2)^2,""),0),"–"),"–") | G39: =IF(AND(ISNUMBER(F39),ISNUMBER(k_hrmax)),ROUND(F39/k_hrmax*100,1),"–")
A40: 4 mmol/L | B40: =IF(k_ok,"Vergleichspunkt","") | C40: =IF(AND(k_ok,ISNUMBER(IF(INDEX(Calc!$E$208:$E$247,5),INDEX(Calc!$D$208:$D$247,5),""))),ROUND(IF(INDEX(Calc!$E$208:$E$247,5),INDEX(Calc!$D$208:$D$247,5),""),k_xd),"–") | D40: =IF(AND(k_ok,k_run,ISNUMBER(IF(INDEX(Calc!$E$208:$E$247,5),INDEX(Calc!$D$208:$D$247,5),""))),IF(N(IF(INDEX(Calc!$E$208:$E$247,5),INDEX(Calc!$D$208:$D$247,5),""))>0,INT(ROUND(3600/(IF(INDEX(Calc!$E$208:$E$247,5),INDEX(Calc!$D$208:$D$247,5),"")),0)/60)&":"&TEXT(MOD(ROUND(3600/(IF(INDEX(Calc!$E$208:$E$247,5),INDEX(Calc!$D$208:$D$247,5),"")),0),60),"00"),"–"),"–") | E40: =IF(AND(k_ok,ISNUMBER(IF(INDEX(Calc!$E$208:$E$247,5),INDEX(Calc!$D$208:$D$247,5),""))),ROUND(4,2),"–") | F40: =IF(AND(k_ok,ISNUMBER(IF(INDEX(Calc!$E$208:$E$247,5),INDEX(Calc!$D$208:$D$247,5),""))),IFERROR(ROUND(IF(k_hrok,k_h0+k_h1*(IF(INDEX(Calc!$E$208:$E$247,5),INDEX(Calc!$D$208:$D$247,5),""))+k_h2*(IF(INDEX(Calc!$E$208:$E$247,5),INDEX(Calc!$D$208:$D$247,5),""))^2,""),0),"–"),"–") | G40: =IF(AND(ISNUMBER(F40),ISNUMBER(k_hrmax)),ROUND(F40/k_hrmax*100,1),"–")
A41: Maximum | B41: =IF(k_ok,"letzte Stufe","") | C41: =IF(AND(k_ok,ISNUMBER(k_hi)),ROUND(k_hi,k_xd),"–") | D41: =IF(AND(k_ok,k_run,ISNUMBER(k_hi)),IF(N(k_hi)>0,INT(ROUND(3600/(k_hi),0)/60)&":"&TEXT(MOD(ROUND(3600/(k_hi),0),60),"00"),"–"),"–") | E41: =IF(AND(k_ok,ISNUMBER(k_hi)),ROUND(k_ylast,2),"–") | F41: =IF(AND(k_ok,ISNUMBER(k_hi)),IFERROR(ROUND(k_hrlast,0),"–"),"–") | G41: =IF(AND(ISNUMBER(F41),ISNUMBER(k_hrmax)),ROUND(F41/k_hrmax*100,1),"–")
A43: Trainingsbereiche
A44: Trainingsbereich | C44: HF von | D44: HF bis | E44: ="von ["&k_unit&"]" | F44: ="bis ["&k_unit&"]" | G44: Pace von | H44: Pace bis
...

Sheet Beispiele
A1: Beispieldaten aus der Webapp
A2: Zum Ausprobieren: Werte in die gelben Felder des Blatts „Eingabe“ kopieren (Messwerte nach Eingabe!B17, Stammdaten einzeln).
A4: Mayer Elisabeth · Laufband 22.09.2026
A5: Name | B5: Mayer Elisabeth
A6: Geburtsdatum | B6: 15.07.2012
A7: Testdatum | B7: 22.09.2026
A8: Größe [cm] | B8: 155.1
A9: Masse [kg] | B9: 40.4
A10: Testleitung | B10: Ernst Johannes, BSc
A11: Stufenhöhe | B11: 1,5 km/h
A12: Ruhelaktat [mmol/L] | B12: 1.6
A13: Ruheglukose [mg/dL] | B13: 81
B14: Zeit | C14: Belastung [km/h] | D14: Laktat [mmol/L] | E14: HF [1/min]
B15: 03:00 | C15: 6 | D15: 2.2 | E15: 145
B16: 06:00 | C16: 7.5 | D16: 2.3 | E16: 167
B17: 09:00 | C17: 9 | D17: 2.7 | E17: 184
B18: 12:00 | C18: 10.5 | D18: 3.5 | E18: 193
B19: 15:00 | C19: 12 | D19: 5.1 | E19: 200
B20: 18:00 | C20: 13.5 | D20: 8.2 | E20: 207
B21: 19:30 | C21: 14.25 | D21: 9.3 | E21: 208
A24: Lan Ryan · Laufband 22.09.2026
A25: Name | B25: Lan Ryan
A26: Geburtsdatum | B26: 12.04.2012
A27: Testdatum | B27: 22.09.2026
A28: Größe [cm] | B28: 163.8
A29: Masse [kg] | B29: 47.5
A30: Testleitung | B30: Ernst Johannes, BSc
A31: Stufenhöhe | B31: 1,5 km/h
A32: Ruhelaktat [mmol/L] | B32: 1.1
A33: Ruheglukose [mg/dL] | B33: 101
B34: Zeit | C34: Belastung [km/h] | D34: Laktat [mmol/L] | E34: HF [1/min]
B35: 03:00 | C35: 6 | D35: 1.6 | E35: 153
B36: 06:00 | C36: 7.5 | D36: 1.7 | E36: 164
B37: 09:00 | C37: 9 | D37: 2.1 | E37: 180
B38: 12:00 | C38: 10.5 | D38: 2.4 | E38: 190
B39: 15:00 | C39: 12 | D39: 3.1 | E39: 199
B40: 18:00 | C40: 13.5 | D40: 4.6 | E40: 211

Sheet Listen
A1: id | B1: Verfahren | C1: Gruppe | D1: Zielkonstrukt | F1: Modell
A2: ltp1h | B2: LTP1 (Hofmann/Pokan) | C2: LT1 | D2: erster Laktatumstellpunkt | F2: Polynom 2. Grades | G2: poly2 | H2: Laufband (km/h) | I2: Kapillar Ohrläppchen | J2: Vollblut | K2: niedrigster Stufenwert | L2: linear | M2: korrigiert: nie unterhalb der Laktatkurve | N2: Nein | O2: mg/dL
A3: ltp1 | B3: LTP1 (3-Phasen global) | C3: LT1 | D3: erster Laktatumstellpunkt | F3: Polynom 3. Grades (Standard für Dmax) | G3: poly3 | H3: Radergometer (W) | I3: Kapillar Finger | J3: Plasma | K3: Ruhelaktat | L3: Polynom 2. Grades | M3: freie Regression durch die Messpunkte | N3: Ja | O3: mmol/L
A4: loglog | B4: Log-Log (Beaver) | C4: LT1 | D4: erster Laktatanstieg | F4: Polynom 4. Grades | G4: poly4 | I4: venös | J4: Hämolysat
A5: b05 | B5: Baseline + 0,5 mmol/L | C5: LT1 | D5: erster Laktatanstieg | F5: Exponentiell a + b·e^(c·x) | G5: exp
A6: lemin | B6: Minimales Laktatäquivalent | C6: LT1 | D6: erster Laktatanstieg
A7: fix2 | B7: fix 2,0 mmol/L | C7: LT1 | D7: niedriger fixer Anker
A8: ltp2h | B8: LTP2 (Hofmann/Pokan) | C8: LT2 | D8: zweiter Laktatumstellpunkt
A9: ltp2 | B9: LTP2 (3-Phasen global) | C9: LT2 | D9: zweiter Laktatumstellpunkt
A10: dmax | B10: Dmax (Cheng) | C10: LT2 | D10: LT2
A11: moddmax | B11: Modified Dmax (Bishop) | C11: LT2 | D11: LT2
A12: lpdmax | B12: Log-Poly-ModDmax | C12: LT2 | D12: LT2 / MLSS-Schätzer
A13: expdmax | B13: Exp-Dmax | C13: LT2 | D13: LT2
A14: dickhuth | B14: Dickhuth (LEmin + 1,5) | C14: LT2 | D14: individuelle obere Schwelle
A15: b10 | B15: Baseline + 1,0 mmol/L | C15: LT2 | D15: Übergangsbereich
A16: b15 | B16: Baseline + 1,5 mmol/L | C16: LT2 | D16: obere Schwelle (Simon-Typ)
A17: fix3 | B17: fix 3,0 mmol/L | C17: FIX | D17: fixer Anker
... A22: lmin | B22: Laktatminimum (Tegtbur) | C22: FIX | D22: nur bei LMT-Protokoll

Sheet Calc
A1: Rechenblatt – kompakte Stufenliste, Parameter, Modellanpassung (nicht bearbeiten)
A2: Zeile | B2: Key x | C2: Key HF | D2: Key Glu | F2: k | G2: x | H2: Quelle | I2: La | J2: HF | K2: gültig | L2: t | M2: t² | N2: t³ | O2: t⁴ | P2: ln x | Q2: ln La | R2: fit P2 | S2: fit P3 | T2: fit P4 | U2: fit Exp | V2: x (Diagr.) | W2: La (Diagr.) | X2: La/x (Diagr.) | Y2: ΔLa | Z2: Baldari | AA2: Guide | AC2: k HF | AD2: x HF | AE2: x² HF | AF2: HF | AG2: x HF (D) | AH2: HF (D) | AJ2: k Glu | AK2: x Glu | AL2: Glu | AM2: Δ | AN2: m roh | AP2: m links | AQ2: m rechts
A3: 1 | B3: =IF(AND(ISNUMBER(Eingabe!$C$17),ISNUMBER(Eingabe!$D$17)),IF(AND(Eingabe!$C$17>0,Eingabe!$D$17>0),Eingabe!$C$17,""),"") | C3: =IF(AND(ISNUMBER(B3),ISNUMBER(Eingabe!$E$17)),IF(Eingabe!$E$17>0,B3,""),"") | D3: =IF(AND(k_gluOn,ISNUMBER(B3),ISNUMBER(Eingabe!$F$17)),IF(Eingabe!$F$17>0,B3,""),"") | F3: 1 | G3: =IF(F3<=k_n,SMALL($B$3:$B$22,F3),0) | H3: =IF(F3<=k_n,MATCH(G3,$B$3:$B$22,0),0) | I3: =IF(F3<=k_n,INDEX(Eingabe!$D$17:$D$36,H3),0) | J3: =IF(F3<=k_n,IF(ISNUMBER(INDEX(Eingabe!$E$17:$E$36,H3)),INDEX(Eingabe!$E$17:$E$36,H3),""),"") | K3: =IF(F3<=k_n,1,0) | L3: =IF(K3=1,(G3-k_mx)/k_sx,0) | M3: =L3^2 | N3: =L3^3 | O3: =L3^4 | P3: =IF(K3=1,LN(G3),0) | Q3: =IF(K3=1,LN(I3),0) | R3: =IF(K3=1,(k_p2_0+((G3)-k_mx)/k_sx*(k_p2_1+((G3)-k_mx)/k_sx*k_p2_2)),0) | S3: =IF(K3=1,(k_p3_0+((G3)-k_mx)/k_sx*(k_p3_1+((G3)-k_mx)/k_sx*(k_p3_2+((G3)-k_mx)/k_sx*k_p3_3))),0) | T3: =IF(K3=1,(k_p4_0+((G3)-k_mx)/k_sx*(k_p4_1+((G3)-k_mx)/k_sx*(k_p4_2+((G3)-k_mx)/k_sx*(k_p4_3+((G3)-k_mx)/k_sx*k_p4_4)))),0) | U3: =IF(K3=1,(k_ea+k_eb*EXP(k_ec*((G3)-k_mx)/k_sx)),0) | V3: =IF(K3=1,G3,NA()) | W3: =IF(K3=1,I3,NA()) | X3: =IF(K3=1,I3/G3,NA()) | Y3: =0 | Z3: =IF(AND(F3>=2,F3<=k_n-1),IF(AND(Y3>=0.5,Y4>=0.5),1,0),0) | AA3: =IF(K3=1,IF(G3<=k_gk1,k_gy0+(k_gy1-k_gy0)*(G3-k_gx0)/(k_gk1-k_gx0),IF(G3<=k_gk2,k_gy1+(k_gy2-k_gy1)*(G3-k_gk1)/(k_gk2-k_gk1),k_gy2+(k_gy3-k_gy2)*(G3-k_gk2)/(k_gx3-k_gk2))),0) | AC3: 1 | AD3: =IF(AC3<=k_nh,SMALL($C$3:$C$22,AC3),0) | AE3: =AD3^2 | AF3: =IF(AC3<=k_nh,INDEX(Eingabe!$E$17:$E$36,MATCH(AD3,$C$3:$C$22,0)),0) | AG3: =IF(AC3<=k_nh,AD3,NA()) | AH3: =IF(AC3<=k_nh,AF3,NA()) | AJ3: 1 | AK3: =IF(AJ3<=k_ng,SMALL($D$3:$D$22,AJ3),0) | AL3: =IF(AJ3<=k_ng,INDEX(Eingabe!$F$17:$F$36,MATCH(AK3,$D$3:$D$22,0)),0) | AM3: =IF(AJ3<k_ng,(AL4-AL3)/(AK4-AK3),0) | AN3: =AO3 | AO3: =IF(AJ3<=k_ng,IF(AJ3=1,AM3,IF(AJ3=k_ng,0,IF(0*AM3<=0,0,(0+AM3)/2))),0) | AP3: =IF(AJ3<k_ng,IF(AM3=0,0,IF((IF(AM3=0,0,AO3/AM3)^2+IF(AM3=0,0,AO4/AM3)^2)>9,3/SQRT((IF(AM3=0,0,AO3/AM3)^2+IF(AM3=0,0,AO4/AM3)^2))*IF(AM3=0,0,AO3/AM3)*AM3,AO3)),0) | AQ3: =IF(AJ3<k_ng,IF(AM3=0,0,IF((IF(AM3=0,0,AO3/AM3)^2+IF(AM3=0,0,AO4/AM3)^2)>9,3/SQRT((IF(AM3=0,0,AO3/AM3)^2+IF(AM3=0,0,AO4/AM3)^2))*IF(AM3=0,0,AO4/AM3)*AM3,AO4)),0) | AR3: =IF(AJ3<=k_ng,AK3,NA()) | AS3: =IF(AJ3<=k_ng,AL3,NA())
